Workbook

Sheet Start Here
A1: Faceless Shorts Performance Tracker: YouTube, TikTok & Reels
A2: For reviewing performance after you post — not a posting calendar or script tool.
A4: Topic | B4: What to do
A5: QUICK START
A6: Step 1 · Settings | B6: Type your channel name, start date (a Monday), weekly goal and currency.
B7: Edit the Niches and Hook types lists to match your channel.
A8: Step 2 · Idea Bank | B8: Add ideas. Score Curiosity, Ease and Evergreen 1–5. 12+ = 🟢 Top pick.
A9: Step 3 · Video Log | B9: About 7 days after posting, add one row per video per platform.
B10: Fill A–O: 6 labels + 7 numbers from analytics (+2 optional affiliate).
A11: Step 4 · Dashboard + Review | B11: Read verdicts, ★ Best rows and Top 5. Write Keep / Stop / Test weekly.
A12: COLOUR KEY
A13: Light yellow | B13: You type here.
A14: Light grey | B14: Formula. Leave it.
A15: Dark row | B15: Headers.
A16: Green | B16: 🟢 Winner, 🟢 Top pick, Vs baseline 1.50 or more.
A17: Red | B17: 🔴 Flop, Vs baseline 0.50 or less.
A18: Orange | B18: ⚠ Not in Settings (Check column).
A19: Light lime | B19: ★ Best (Dashboard). Dashboard text bars are green.
A20: THE 7 TABS
A21: Settings | B21: Channel name, start date, weekly goal, currency and your lists.
A22: Idea Bank | B22: Score = Curiosity + Ease + Evergreen. 12+ = Top pick.
A23: Video Log | B23: One row per video per platform. Baseline, Vs baseline, Verdict.
A24: Revenue Estimator | B24: 12 months. Ad = views × RPM ÷ 1000. Affiliate summed from Video Log.
A25: Dashboard | B25: 6 KPIs, Top 5, 4 comparison tables, Same video across platforms.
A26: Weekly Review | B26: 12 week slots (weeks 5+ fill in after you copy rows down).
A27: LABELS
A28: Baseline | B28: Average 7-day views of your OTHER posts, same platform + length bucket.
A29: Vs baseline | B29: 7-day views ÷ Baseline, rounded to 2 decimals.
A30: Verdict | B30: 1.50 or more = 🟢 Winner. 0.50 or less = 🔴 Flop. Otherwise Normal.
A31: Need 3+ | B31: Fewer than 3 other posts in the same platform + length bucket.
A32: — (dash) | B32: No baseline yet, or not posted on that platform.
A33: Check | B33: ⚠ Not in Settings = niche, hook or platform not spelled as in Settings.
A34: HOW THE BASELINE WORKS | B34: Each post is compared with the average of your OTHER posts on the same
B35: platform and length bucket — at least 3 others, otherwise 'Need 3+'.
A36: CLEAR THE SAMPLE DATA | B36: Select each range and press Delete. Clear cells; do not delete rows.
A37: Idea Bank | B37: B5:H34 and K5:L34
A38: Video Log | B38: A5:O40
A39: Revenue Estimator | B39: B5:C6, E5:F6, H5:I6, K5:L6 and Sponsors / Other O5:O6
A40: Weekly Review | B40: Keep / Stop / Test notes H5:J6
A41: Settings | B41: Change B5:B8 to your own values. Keep or edit the lists.
...

Sheet Settings
A1: Settings
A2: Light yellow = you type. The lists feed the dropdown checks and the Dashboard. Room to row 34.
A4: Setting | B4: Value | C4: Note | D4: Niches | E4: Hook types | F4: Platforms | G4: Status | H4: Length buckets
A5: Channel name | B5: My Faceless Channel | C5: For your reference | D5: Reddit Stories | E5: Question | F5: YouTube Shorts | G5: Idea | H5: ≤15s
A6: Start date (a Monday) | B6: 46286 | C6: Week 1 of Weekly Review starts here | D6: History Facts | E6: Shocking Fact | F6: TikTok | G6: Testing | H6: 16–30s
A7: Weekly posting goal | B7: 15 | C7: 5 videos × 3 platforms = 15 posts | D7: Motivation | E7: Story Cold Open | F7: Instagram Reels | G7: Scripted | H7: 31–45s
A8: Currency symbol | B8: $ | C8: Money cells use $; change the format for others | D8: AI Tools | E8: You won't believe | F8: Facebook Reels | G8: Edited | H8: 46–60s
D9: True Crime | E9: List / Countdown | G9: Scheduled | H9: 61s+
D10: Finance Facts | E10: Myth vs Truth | G10: Posted
D11: Science Facts | E11: POV | G11: Dropped
D12: Beauty & Skincare | E12: Challenge
D13: Fitness & Health | E13: Before/After
D14: Other | E14: Direct Promise

Sheet Idea Bank
A1: Idea Bank
A2: Score each idea 1–5. Score 12+ = 🟢 Top pick. Sample ideas (rows 5–34) are fictional. Formulas run to row 64.
A4: ID | B4: Idea | C4: Niche | D4: Hook type | E4: Source | F4: Curiosity 1–5 | G4: Ease 1–5 | H4: Evergreen 1–5 | I4: Score | J4: Pick | K4: Status | L4: Notes | M4: Check
A5: =IF(B5="","",ROW()-4) | B5: The note under the door | C5: Reddit Stories | D5: Story Cold Open | E5: Own idea | F5: 5 | G5: 4 | H5: 4 | I5: =IF(B5="","",SUM(F5:H5)) | J5: =IF(I5="","",IF(I5>=12,"🟢 Top pick","")) | K5: Posted | L5: Posted 2026-09-21 | M5: =IF((COUNTIF(Settings!$D$5:$D$34,C5)+(C5=""))*(COUNTIF(Settings!$E$5:$E$34,D5)+(D5="")),"","⚠ Not in Settings")
A6: =IF(B6="","",ROW()-4) | B6: My roommate's 3 rules | C6: Reddit Stories | D6: List / Countdown | E6: Own idea | F6: 4 | G6: 3 | H6: 4 | I6: =IF(B6="","",SUM(F6:H6)) | J6: =IF(I6="","",IF(I6>=12,"🟢 Top pick","")) | K6: Posted | L6: 47s: trim next time | M6: =IF((COUNTIF(Settings!$D$5:$D$34,C6)+(C6=""))*(COUNTIF(Settings!$E$5:$E$34,D6)+(D6="")),"","⚠ Not in Settings")
A7: =IF(B7="","",ROW()-4) | B7: My boss hit reply all | C7: Reddit Stories | D7: Story Cold Open | E7: Comment request | F7: 5 | G7: 4 | H7: 3 | I7: =IF(B7="","",SUM(F7:H7)) | J7: =IF(I7="","",IF(I7>=12,"🟢 Top pick","")) | K7: Posted | M7: =IF((COUNTIF(Settings!$D$5:$D$34,C7)+(C7=""))*(COUNTIF(Settings!$E$5:$E$34,D7)+(D7="")),"","⚠ Not in Settings")
A8: =IF(B8="","",ROW()-4) | B8: The neighbor who returned my packages | C8: Reddit Stories | D8: POV | E8: Own idea | F8: 4 | G8: 4 | H8: 4 | I8: =IF(B8="","",SUM(F8:H8)) | J8: =IF(I8="","",IF(I8>=12,"🟢 Top pick","")) | K8: Posted | M8: =IF((COUNTIF(Settings!$D$5:$D$34,C8)+(C8=""))*(COUNTIF(Settings!$E$5:$E$34,D8)+(D8="")),"","⚠ Not in Settings")
A9: =IF(B9="","",ROW()-4) | B9: The wedding gift receipt | C9: Reddit Stories | D9: Question | E9: Own idea | F9: 5 | G9: 3 | H9: 4 | I9: =IF(B9="","",SUM(F9:H9)) | J9: =IF(I9="","",IF(I9>=12,"🟢 Top pick","")) | K9: Posted | M9: =IF((COUNTIF(Settings!$D$5:$D$34,C9)+(C9=""))*(COUNTIF(Settings!$E$5:$E$34,D9)+(D9="")),"","⚠ Not in Settings")
A10: =IF(B10="","",ROW()-4) | B10: 3 red flags at my first apartment viewing | C10: Reddit Stories | D10: List / Countdown | E10: Own idea | F10: 3 | G10: 4 | H10: 4 | I10: =IF(B10="","",SUM(F10:H10)) | J10: =IF(I10="","",IF(I10>=12,"🟢 Top pick","")) | K10: Posted | M10: =IF((COUNTIF(Settings!$D$5:$D$34,C10)+(C10=""))*(COUNTIF(Settings!$E$5:$E$34,D10)+(D10="")),"","⚠ Not in Settings")
A11: =IF(B11="","",ROW()-4) | B11: The coworker who labeled everything in the fridge | C11: Reddit Stories | D11: Story Cold Open | E11: Own idea | F11: 4 | G11: 4 | H11: 5 | I11: =IF(B11="","",SUM(F11:H11)) | J11: =IF(I11="","",IF(I11>=12,"🟢 Top pick","")) | K11: Scripted | L11: Part 2 possible | M11: =IF((COUNTIF(Settings!$D$5:$D$34,C11)+(C11=""))*(COUNTIF(Settings!$E$5:$E$34,D11)+(D11="")),"","⚠ Not in Settings")
A12: =IF(B12="","",ROW()-4) | B12: My landlord's surprise inspection | C12: Reddit Stories | D12: POV | E12: Comment request | F12: 3 | G12: 4 | H12: 3 | I12: =IF(B12="","",SUM(F12:H12)) | J12: =IF(I12="","",IF(I12>=12,"🟢 Top pick","")) | K12: Idea | M12: =IF((COUNTIF(Settings!$D$5:$D$34,C12)+(C12=""))*(COUNTIF(Settings!$E$5:$E$34,D12)+(D12="")),"","⚠ Not in Settings")
A13: =IF(B13="","",ROW()-4) | B13: The group project nobody else did | C13: Reddit Stories | D13: Question | E13: Own idea | F13: 4 | G13: 5 | H13: 4 | I13: =IF(B13="","",SUM(F13:H13)) | J13: =IF(I13="","",IF(I13>=12,"🟢 Top pick","")) | K13: Scripted | M13: =IF((COUNTIF(Settings!$D$5:$D$34,C13)+(C13=""))*(COUNTIF(Settings!$E$5:$E$34,D13)+(D13="")),"","⚠ Not in Settings")
A14: =IF(B14="","",ROW()-4) | B14: The dog that kept bringing home one shoe | C14: Reddit Stories | D14: Story Cold Open | E14: Own idea | F14: 5 | G14: 4 | H14: 4 | I14: =IF(B14="","",SUM(F14:H14)) | J14: =IF(I14="","",IF(I14>=12,"🟢 Top pick","")) | K14: Testing | L14: Try both hooks | M14: =IF((COUNTIF(Settings!$D$5:$D$34,C14)+(C14=""))*(COUNTIF(Settings!$E$5:$E$34,D14)+(D14="")),"","⚠ Not in Settings")
A15: =IF(B15="","",ROW()-4) | B15: My sister's secret second job | C15: Reddit Stories | D15: You won't believe | E15: Own idea | F15: 5 | G15: 3 | H15: 4 | I15: =IF(B15="","",SUM(F15:H15)) | J15: =IF(I15="","",IF(I15>=12,"🟢 Top pick","")) | K15: Idea | M15: =IF((COUNTIF(Settings!$D$5:$D$34,C15)+(C15=""))*(COUNTIF(Settings!$E$5:$E$34,D15)+(D15="")),"","⚠ Not in Settings")
A16: =IF(B16="","",ROW()-4) | B16: The voicemail from a wrong number | C16: Reddit Stories | D16: Story Cold Open | E16: Own idea | F16: 5 | G16: 4 | H16: 3 | I16: =IF(B16="","",SUM(F16:H16)) | J16: =IF(I16="","",IF(I16>=12,"🟢 Top pick","")) | K16: Idea | M16: =IF((COUNTIF(Settings!$D$5:$D$34,C16)+(C16=""))*(COUNTIF(Settings!$E$5:$E$34,D16)+(D16="")),"","⚠ Not in Settings")
A17: =IF(B17="","",ROW()-4) | B17: The gym locker mix-up | C17: Reddit Stories | D17: POV | E17: Own idea | F17: 3 | G17: 4 | H17: 3 | I17: =IF(B17="","",SUM(F17:H17)) | J17: =IF(I17="","",IF(I17>=12,"🟢 Top pick","")) | K17: Idea | M17: =IF((COUNTIF(Settings!$D$5:$D$34,C17)+(C17=""))*(COUNTIF(Settings!$E$5:$E$34,D17)+(D17="")),"","⚠ Not in Settings")
A18: =IF(B18="","",ROW()-4) | B18: The neighbor's 6 a.m. leaf blower | C18: Reddit Stories | D18: Question | E18: Comment request | F18: 4 | G18: 4 | H18: 4 | I18: =IF(B18="","",SUM(F18:H18)) | J18: =IF(I18="","",IF(I18>=12,"🟢 Top pick","")) | K18: Idea | M18: =IF((COUNTIF(Settings!$D$5:$D$34,C18)+(C18=""))*(COUNTIF(Settings!$E$5:$E$34,D18)+(D18="")),"","⚠ Not in Settings")
A19: =IF(B19="","",ROW()-4) | B19: The car I almost bought | C19: Reddit Stories | D19: Story Cold Open | E19: Own idea | F19: 3 | G19: 3 | H19: 4 | I19: =IF(B19="","",SUM(F19:H19)) | J19: =IF(I19="","",IF(I19>=12,"🟢 Top pick","")) | K19: Dropped | L19: Too close to ID 6 | M19: =IF((COUNTIF(Settings!$D$5:$D$34,C19)+(C19=""))*(COUNTIF(Settings!$E$5:$E$34,D19)+(D19="")),"","⚠ Not in Settings")
A20: =IF(B20="","",ROW()-4) | B20: Rome's 6-month dictator | C20: History Facts | D20: Shocking Fact | E20: Library book | F20: 4 | G20: 4 | H20: 5 | I20: =IF(B20="","",SUM(F20:H20)) | J20: =IF(I20="","",IF(I20>=12,"🟢 Top pick","")) | K20: Posted | M20: =IF((COUNTIF(Settings!$D$5:$D$34,C20)+(C20=""))*(COUNTIF(Settings!$E$5:$E$34,D20)+(D20="")),"","⚠ Not in Settings")
A21: =IF(B21="","",ROW()-4) | B21: Can you see the Great Wall from space? | C21: History Facts | D21: Myth vs Truth | E21: Encyclopedia | F21: 4 | G21: 4 | H21: 5 | I21: =IF(B21="","",SUM(F21:H21)) | J21: =IF(I21="","",IF(I21>=12,"🟢 Top pick","")) | K21: Posted | M21: =IF((COUNTIF(Settings!$D$5:$D$34,C21)+(C21=""))*(COUNTIF(Settings!$E$5:$E$34,D21)+(D21="")),"","⚠ Not in Settings")
A22: =IF(B22="","",ROW()-4) | B22: Napoleon wasn't short | C22: History Facts | D22: Myth vs Truth | E22: Encyclopedia | F22: 4 | G22: 5 | H22: 5 | I22: =IF(B22="","",SUM(F22:H22)) | J22: =IF(I22="","",IF(I22>=12,"🟢 Top pick","")) | K22: Posted | M22: =IF((COUNTIF(Settings!$D$5:$D$34,C22)+(C22=""))*(COUNTIF(Settings!$E$5:$E$34,D22)+(D22="")),"","⚠ Not in Settings")
A23: =IF(B23="","",ROW()-4) | B23: The 38-minute war | C23: History Facts | D23: Shocking Fact | E23: Encyclopedia | F23: 5 | G23: 4 | H23: 5 | I23: =IF(B23="","",SUM(F23:H23)) | J23: =IF(I23="","",IF(I23>=12,"🟢 Top pick","")) | K23: Posted | M23: =IF((COUNTIF(Settings!$D$5:$D$34,C23)+(C23=""))*(COUNTIF(Settings!$E$5:$E$34,D23)+(D23="")),"","⚠ Not in Settings")
A24: =IF(B24="","",ROW()-4) | B24: The Great Emu War | C24: History Facts | D24: You won't believe | E24: Library book | F24: 5 | G24: 4 | H24: 5 | I24: =IF(B24="","",SUM(F24:H24)) | J24: =IF(I24="","",IF(I24>=12,"🟢 Top pick","")) | K24: Posted | M24: =IF((COUNTIF(Settings!$D$5:$D$34,C24)+(C24=""))*(COUNTIF(Settings!$E$5:$E$34,D24)+(D24="")),"","⚠ Not in Settings")
A25: =IF(B25="","",ROW()-4) | B25: Cleopatra lived closer to the Moon landing | C25: History Facts | D25: You won't believe | E25: Encyclopedia | F25: 5 | G25: 4 | H25: 5 | I25: =IF(B25="","",SUM(F25:H25)) | J25: =IF(I25="","",IF(I25>=12,"🟢 Top pick","")) | K25: Posted | M25: =IF((COUNTIF(Settings!$D$5:$D$34,C25)+(C25=""))*(COUNTIF(Settings!$E$5:$E$34,D25)+(D25="")),"","⚠ Not in Settings")
A26: =IF(B26="","",ROW()-4) | B26: Medieval courts that put animals on trial | C26: History Facts | D26: You won't believe | E26: Library book | F26: 5 | G26: 3 | H26: 4 | I26: =IF(B26="","",SUM(F26:H26)) | J26: =IF(I26="","",IF(I26>=12,"🟢 Top pick","")) | K26: Scripted | L26: Check 2 sources | M26: =IF((COUNTIF(Settings!$D$5:$D$34,C26)+(C26=""))*(COUNTIF(Settings!$E$5:$E$34,D26)+(D26="")),"","⚠ Not in Settings")
A27: =IF(B27="","",ROW()-4) | B27: The dancing plague of 1518 | C27: History Facts | D27: Shocking Fact | E27: Encyclopedia | F27: 5 | G27: 3 | H27: 5 | I27: =IF(B27="","",SUM(F27:H27)) | J27: =IF(I27="","",IF(I27>=12,"🟢 Top pick","")) | K27: Testing | M27: =IF((COUNTIF(Settings!$D$5:$D$34,C27)+(C27=""))*(COUNTIF(Settings!$E$5:$E$34,D27)+(D27="")),"","⚠ Not in Settings")
A28: =IF(B28="","",ROW()-4) | B28: The Year Without a Summer (1816) | C28: History Facts | D28: Question | E28: Library book | F28: 4 | G28: 4 | H28: 4 | I28: =IF(B28="","",SUM(F28:H28)) | J28: =IF(I28="","",IF(I28>=12,"🟢 Top pick","")) | K28: Idea | M28: =IF((COUNTIF(Settings!$D$5:$D$34,C28)+(C28=""))*(COUNTIF(Settings!$E$5:$E$34,D28)+(D28="")),"","⚠ Not in Settings")
A29: =IF(B29="","",ROW()-4) | B29: How medieval people kept food cold | C29: History Facts | D29: Question | E29: Comment request | F29: 3 | G29: 3 | H29: 4 | I29: =IF(B29="","",SUM(F29:H29)) | J29: =IF(I29="","",IF(I29>=12,"🟢 Top pick","")) | K29: Idea | M29: =IF((COUNTIF(Settings!$D$5:$D$34,C29)+(C29=""))*(COUNTIF(Settings!$E$5:$E$34,D29)+(D29="")),"","⚠ Not in Settings")
A30: =IF(B30="","",ROW()-4) | B30: When the US mail delivered children | C30: History Facts | D30: You won't believe | E30: Encyclopedia | F30: 4 | G30: 2 | H30: 4 | I30: =IF(B30="","",SUM(F30:H30)) | J30: =IF(I30="","",IF(I30>=12,"🟢 Top pick","")) | K30: Idea | L30: Check 2 sources | M30: =IF((COUNTIF(Settings!$D$5:$D$34,C30)+(C30=""))*(COUNTIF(Settings!$E$5:$E$34,D30)+(D30="")),"","⚠ Not in Settings")
A31: =IF(B31="","",ROW()-4) | B31: How sailors told time at sea | C31: History Facts | D31: Question | E31: Library book | F31: 2 | G31: 3 | H31: 4 | I31: =IF(B31="","",SUM(F31:H31)) | J31: =IF(I31="","",IF(I31>=12,"🟢 Top pick","")) | K31: Idea | M31: =IF((COUNTIF(Settings!$D$5:$D$34,C31)+(C31=""))*(COUNTIF(Settings!$E$5:$E$34,D31)+(D31="")),"","⚠ Not in Settings")
A32: =IF(B32="","",ROW()-4) | B32: Why old maps had sea monsters | C32: History Facts | D32: Myth vs Truth | E32: Library book | F32: 3 | G32: 3 | H32: 4 | I32: =IF(B32="","",SUM(F32:H32)) | J32: =IF(I32="","",IF(I32>=12,"🟢 Top pick","")) | K32: Idea | M32: =IF((COUNTIF(Settings!$D$5:$D$34,C32)+(C32=""))*(COUNTIF(Settings!$E$5:$E$34,D32)+(D32="")),"","⚠ Not in Settings")
A33: =IF(B33="","",ROW()-4) | B33: Where the 7-day week came from | C33: History Facts | D33: Question | E33: Encyclopedia | F33: 2 | G33: 3 | H33: 5 | I33: =IF(B33="","",SUM(F33:H33)) | J33: =IF(I33="","",IF(I33>=12,"🟢 Top pick","")) | K33: Idea | M33: =IF((COUNTIF(Settings!$D$5:$D$34,C33)+(C33=""))*(COUNTIF(Settings!$E$5:$E$34,D33)+(D33="")),"","⚠ Not in Settings")
A34: =IF(B34="","",ROW()-4) | B34: Old London Bridge had houses on it | C34: History Facts | D34: Shocking Fact | E34: Library book | F34: 2 | G34: 3 | H34: 3 | I34: =IF(B34="","",SUM(F34:H34)) | J34: =IF(I34="","",IF(I34>=12,"🟢 Top pick","")) | K34: Idea | M34: =IF((COUNTIF(Settings!$D$5:$D$34,C34)+(C34=""))*(COUNTIF(Settings!$E$5:$E$34,D34)+(D34="")),"","⚠ Not in Settings")
A35: =IF(B35="","",ROW()-4) | I35: =IF(B35="","",SUM(F35:H35)) | J35: =IF(I35="","",IF(I35>=12,"🟢 Top pick","")) | M35: =IF((COUNTIF(Settings!$D$5:$D$34,C35)+(C35=""))*(COUNTIF(Settings!$E$5:$E$34,D35)+(D35="")),"","⚠ Not in Settings")
A36: =IF(B36="","",ROW()-4) | I36: =IF(B36="","",SUM(F36:H36)) | J36: =IF(I36="","",IF(I36>=12,"🟢 Top pick","")) | M36: =IF((COUNTIF(Settings!$D$5:$D$34,C36)+(C36=""))*(COUNTIF(Settings!$E$5:$E$34,D36)+(D36="")),"","⚠ Not in Settings")
A37: =IF(B37="","",ROW()-4) | I37: =IF(B37="","",SUM(F37:H37)) | J37: =IF(I37="","",IF(I37>=12,"🟢 Top pick","")) | M37: =IF((COUNTIF(Settings!$D$5:$D$34,C37)+(C37=""))*(COUNTIF(Settings!$E$5:$E$34,D37)+(D37="")),"","⚠ Not in Settings")
A38: =IF(B38="","",ROW()-4) | I38: =IF(B38="","",SUM(F38:H38)) | J38: =IF(I38="","",IF(I38>=12,"🟢 Top pick","")) | M38: =IF((COUNTIF(Settings!$D$5:$D$34,C38)+(C38=""))*(COUNTIF(Settings!$E$5:$E$34,D38)+(D38="")),"","⚠ Not in Settings")
A39: =IF(B39="","",ROW()-4) | I39: =IF(B39="","",SUM(F39:H39)) | J39: =IF(I39="","",IF(I39>=12,"🟢 Top pick","")) | M39: =IF((COUNTIF(Settings!$D$5:$D$34,C39)+(C39=""))*(COUNTIF(Settings!$E$5:$E$34,D39)+(D39="")),"","⚠ Not in Settings")
A40: =IF(B40="","",ROW()-4) | I40: =IF(B40="","",SUM(F40:H40)) | J40: =IF(I40="","",IF(I40>=12,"🟢 Top pick","")) | M40: =IF((COUNTIF(Settings!$D$5:$D$34,C40)+(C40=""))*(COUNTIF(Settings!$E$5:$E$34,D40)+(D40="")),"","⚠ Not in Settings")
A41: =IF(B41="","",ROW()-4) | I41: =IF(B41="","",SUM(F41:H41)) | J41: =IF(I41="","",IF(I41>=12,"🟢 Top pick","")) | M41: =IF((COUNTIF(Settings!$D$5:$D$34,C41)+(C41=""))*(COUNTIF(Settings!$E$5:$E$34,D41)+(D41="")),"","⚠ Not in Settings")
...

Sheet Video Log
A1: Video Log
A2: Sample data: fictional numbers. Clear the light-yellow cells in rows 5–40 (A5:O40) before you start. One row per video per platform.
A4: Post date | B4: Title | C4: Niche | D4: Hook type | E4: Platform | F4: Length (s) | G4: Views 48h | H4: Views 7d | I4: Avg % viewed | J4: Likes | K4: Comments | L4: Shares | M4: Follows | N4: Affiliate clicks | O4: Affiliate revenue | P4: Length bucket | Q4: Engagement | R4: Baseline | S4: Vs baseline | T4: Verdict | U4: % viewed | V4: Check | W4: Key: rank | X4: Key: week | Y4: Key: first row | Z4: Key: title+platform | AA4: Key: last date
A5: 46286 | B5: The note under the door | C5: Reddit Stories | D5: Story Cold Open | E5: YouTube Shorts | F5: 41 | G5: 1230 | H5: 2050 | I5: 0.71 | J5: 123 | K5: 16 | L5: 8 | M5: 5 | P5: =IF(F5="","",INDEX(Settings!$H$5:$H$9,1+(F5>15)+(F5>30)+(F5>45)+(F5>60))) | Q5: =IFERROR((J5+K5+L5)/H5,"") | R5: =IF(H5="","",IF(COUNTIFS(E:E,E5,P:P,P5,H:H,">=0")-1<3,"Need 3+",(SUMIFS(H:H,E:E,E5,P:P,P5)-H5)/(COUNTIFS(E:E,E5,P:P,P5,H:H,">=0")-1))) | S5: =IF(H5="","",IFERROR(ROUND(H5/R5,2),"—")) | T5: =IF(H5="","",IF(S5="—","—",IF(S5>=1.5,"🟢 Winner",IF(S5<=0.5,"🔴 Flop","Normal")))) | U5: =IF(I5="","",IF(I5>1,I5/100,I5)) | V5: =IF((COUNTIF(Settings!$D$5:$D$34,C5)+(C5=""))*(COUNTIF(Settings!$E$5:$E$34,D5)+(D5=""))*(COUNTIF(Settings!$F$5:$F$34,E5)+(E5="")),"","⚠ Not in Settings") | W5: =IF(H5="","",H5+ROW()/10000) | X5: =IF(OR(A5="",W5=""),"",(INT((A5-Settings!$B$6)/7)+1)*1E10+W5) | Y5: =IF(B5="","",IF(COUNTIF(B$5:B5,B5)=1,ROW(),"")) | Z5: =IF(H5="","",B5&"|"&E5) | AA5: =IF(B5="","",IF(COUNTIF(B5:B$1000,B5)=1,A5,""))
A6: 46286 | B6: The note under the door | C6: Reddit Stories | D6: Story Cold Open | E6: TikTok | F6: 41 | G6: 2052 | H6: 3420 | I6: 0.78 | J6: 205 | K6: 27 | L6: 14 | M6: 9 | N6: 9 | O6: 3.6 | P6: =IF(F6="","",INDEX(Settings!$H$5:$H$9,1+(F6>15)+(F6>30)+(F6>45)+(F6>60))) | Q6: =IFERROR((J6+K6+L6)/H6,"") | R6: =IF(H6="","",IF(COUNTIFS(E:E,E6,P:P,P6,H:H,">=0")-1<3,"Need 3+",(SUMIFS(H:H,E:E,E6,P:P,P6)-H6)/(COUNTIFS(E:E,E6,P:P,P6,H:H,">=0")-1))) | S6: =IF(H6="","",IFERROR(ROUND(H6/R6,2),"—")) | T6: =IF(H6="","",IF(S6="—","—",IF(S6>=1.5,"🟢 Winner",IF(S6<=0.5,"🔴 Flop","Normal")))) | U6: =IF(I6="","",IF(I6>1,I6/100,I6)) | V6: =IF((COUNTIF(Settings!$D$5:$D$34,C6)+(C6=""))*(COUNTIF(Settings!$E$5:$E$34,D6)+(D6=""))*(COUNTIF(Settings!$F$5:$F$34,E6)+(E6="")),"","⚠ Not in Settings") | W6: =IF(H6="","",H6+ROW()/10000) | X6: =IF(OR(A6="",W6=""),"",(INT((A6-Settings!$B$6)/7)+1)*1E10+W6) | Y6: =IF(B6="","",IF(COUNTIF(B$5:B6,B6)=1,ROW(),"")) | Z6: =IF(H6="","",B6&"|"&E6) | AA6: =IF(B6="","",IF(COUNTIF(B6:B$1000,B6)=1,A6,""))
A7: 46286 | B7: The note under the door | C7: Reddit Stories | D7: Story Cold Open | E7: Instagram Reels | F7: 41 | G7: 690 | H7: 1150 | I7: 0.66 | J7: 69 | K7: 9 | L7: 5 | M7: 3 | P7: =IF(F7="","",INDEX(Settings!$H$5:$H$9,1+(F7>15)+(F7>30)+(F7>45)+(F7>60))) | Q7: =IFERROR((J7+K7+L7)/H7,"") | R7: =IF(H7="","",IF(COUNTIFS(E:E,E7,P:P,P7,H:H,">=0")-1<3,"Need 3+",(SUMIFS(H:H,E:E,E7,P:P,P7)-H7)/(COUNTIFS(E:E,E7,P:P,P7,H:H,">=0")-1))) | S7: =IF(H7="","",IFERROR(ROUND(H7/R7,2),"—")) | T7: =IF(H7="","",IF(S7="—","—",IF(S7>=1.5,"🟢 Winner",IF(S7<=0.5,"🔴 Flop","Normal")))) | U7: =IF(I7="","",IF(I7>1,I7/100,I7)) | V7: =IF((COUNTIF(Settings!$D$5:$D$34,C7)+(C7=""))*(COUNTIF(Settings!$E$5:$E$34,D7)+(D7=""))*(COUNTIF(Settings!$F$5:$F$34,E7)+(E7="")),"","⚠ Not in Settings") | W7: =IF(H7="","",H7+ROW()/10000) | X7: =IF(OR(A7="",W7=""),"",(INT((A7-Settings!$B$6)/7)+1)*1E10+W7) | Y7: =IF(B7="","",IF(COUNTIF(B$5:B7,B7)=1,ROW(),"")) | Z7: =IF(H7="","",B7&"|"&E7) | AA7: =IF(B7="","",IF(COUNTIF(B7:B$1000,B7)=1,A7,""))
A8: 46287 | B8: Rome's 6-month dictator | C8: History Facts | D8: Shocking Fact | E8: YouTube Shorts | F8: 28 | G8: 786 | H8: 1310 | I8: 0.84 | J8: 79 | K8: 10 | L8: 5 | M8: 3 | P8: =IF(F8="","",INDEX(Settings!$H$5:$H$9,1+(F8>15)+(F8>30)+(F8>45)+(F8>60))) | Q8: =IFERROR((J8+K8+L8)/H8,"") | R8: =IF(H8="","",IF(COUNTIFS(E:E,E8,P:P,P8,H:H,">=0")-1<3,"Need 3+",(SUMIFS(H:H,E:E,E8,P:P,P8)-H8)/(COUNTIFS(E:E,E8,P:P,P8,H:H,">=0")-1))) | S8: =IF(H8="","",IFERROR(ROUND(H8/R8,2),"—")) | T8: =IF(H8="","",IF(S8="—","—",IF(S8>=1.5,"🟢 Winner",IF(S8<=0.5,"🔴 Flop","Normal")))) | U8: =IF(I8="","",IF(I8>1,I8/100,I8)) | V8: =IF((COUNTIF(Settings!$D$5:$D$34,C8)+(C8=""))*(COUNTIF(Settings!$E$5:$E$34,D8)+(D8=""))*(COUNTIF(Settings!$F$5:$F$34,E8)+(E8="")),"","⚠ Not in Settings") | W8: =IF(H8="","",H8+ROW()/10000) | X8: =IF(OR(A8="",W8=""),"",(INT((A8-Settings!$B$6)/7)+1)*1E10+W8) | Y8: =IF(B8="","",IF(COUNTIF(B$5:B8,B8)=1,ROW(),"")) | Z8: =IF(H8="","",B8&"|"&E8) | AA8: =IF(B8="","",IF(COUNTIF(B8:B$1000,B8)=1,A8,""))
A9: 46287 | B9: Rome's 6-month dictator | C9: History Facts | D9: Shocking Fact | E9: TikTok | F9: 28 | G9: 1260 | H9: 2100 | I9: 0.79 | J9: 126 | K9: 17 | L9: 8 | M9: 5 | P9: =IF(F9="","",INDEX(Settings!$H$5:$H$9,1+(F9>15)+(F9>30)+(F9>45)+(F9>60))) | Q9: =IFERROR((J9+K9+L9)/H9,"") | R9: =IF(H9="","",IF(COUNTIFS(E:E,E9,P:P,P9,H:H,">=0")-1<3,"Need 3+",(SUMIFS(H:H,E:E,E9,P:P,P9)-H9)/(COUNTIFS(E:E,E9,P:P,P9,H:H,">=0")-1))) | S9: =IF(H9="","",IFERROR(ROUND(H9/R9,2),"—")) | T9: =IF(H9="","",IF(S9="—","—",IF(S9>=1.5,"🟢 Winner",IF(S9<=0.5,"🔴 Flop","Normal")))) | U9: =IF(I9="","",IF(I9>1,I9/100,I9)) | V9: =IF((COUNTIF(Settings!$D$5:$D$34,C9)+(C9=""))*(COUNTIF(Settings!$E$5:$E$34,D9)+(D9=""))*(COUNTIF(Settings!$F$5:$F$34,E9)+(E9="")),"","⚠ Not in Settings") | W9: =IF(H9="","",H9+ROW()/10000) | X9: =IF(OR(A9="",W9=""),"",(INT((A9-Settings!$B$6)/7)+1)*1E10+W9) | Y9: =IF(B9="","",IF(COUNTIF(B$5:B9,B9)=1,ROW(),"")) | Z9: =IF(H9="","",B9&"|"&E9) | AA9: =IF(B9="","",IF(COUNTIF(B9:B$1000,B9)=1,A9,""))
A10: 46287 | B10: Rome's 6-month dictator | C10: History Facts | D10: Shocking Fact | E10: Instagram Reels | F10: 28 | G10: 456 | H10: 760 | I10: 0.75 | J10: 46 | K10: 6 | L10: 3 | M10: 2 | P10: =IF(F10="","",INDEX(Settings!$H$5:$H$9,1+(F10>15)+(F10>30)+(F10>45)+(F10>60))) | Q10: =IFERROR((J10+K10+L10)/H10,"") | R10: =IF(H10="","",IF(COUNTIFS(E:E,E10,P:P,P10,H:H,">=0")-1<3,"Need 3+",(SUMIFS(H:H,E:E,E10,P:P,P10)-H10)/(COUNTIFS(E:E,E10,P:P,P10,H:H,">=0")-1))) | S10: =IF(H10="","",IFERROR(ROUND(H10/R10,2),"—")) | T10: =IF(H10="","",IF(S10="—","—",IF(S10>=1.5,"🟢 Winner",IF(S10<=0.5,"🔴 Flop","Normal")))) | U10: =IF(I10="","",IF(I10>1,I10/100,I10)) | V10: =IF((COUNTIF(Settings!$D$5:$D$34,C10)+(C10=""))*(COUNTIF(Settings!$E$5:$E$34,D10)+(D10=""))*(COUNTIF(Settings!$F$5:$F$34,E10)+(E10="")),"","⚠ Not in Settings") | W10: =IF(H10="","",H10+ROW()/10000) | X10: =IF(OR(A10="",W10=""),"",(INT((A10-Settings!$B$6)/7)+1)*1E10+W10) | Y10: =IF(B10="","",IF(COUNTIF(B$5:B10,B10)=1,ROW(),"")) | Z10: =IF(H10="","",B10&"|"&E10) | AA10: =IF(B10="","",IF(COUNTIF(B10:B$1000,B10)=1,A10,""))
A11: 46288 | B11: My roommate's 3 rules | C11: Reddit Stories | D11: List / Countdown | E11: YouTube Shorts | F11: 47 | G11: 540 | H11: 900 | I11: 0.52 | J11: 54 | K11: 7 | L11: 4 | M11: 2 | P11: =IF(F11="","",INDEX(Settings!$H$5:$H$9,1+(F11>15)+(F11>30)+(F11>45)+(F11>60))) | Q11: =IFERROR((J11+K11+L11)/H11,"") | R11: =IF(H11="","",IF(COUNTIFS(E:E,E11,P:P,P11,H:H,">=0")-1<3,"Need 3+",(SUMIFS(H:H,E:E,E11,P:P,P11)-H11)/(COUNTIFS(E:E,E11,P:P,P11,H:H,">=0")-1))) | S11: =IF(H11="","",IFERROR(ROUND(H11/R11,2),"—")) | T11: =IF(H11="","",IF(S11="—","—",IF(S11>=1.5,"🟢 Winner",IF(S11<=0.5,"🔴 Flop","Normal")))) | U11: =IF(I11="","",IF(I11>1,I11/100,I11)) | V11: =IF((COUNTIF(Settings!$D$5:$D$34,C11)+(C11=""))*(COUNTIF(Settings!$E$5:$E$34,D11)+(D11=""))*(COUNTIF(Settings!$F$5:$F$34,E11)+(E11="")),"","⚠ Not in Settings") | W11: =IF(H11="","",H11+ROW()/10000) | X11: =IF(OR(A11="",W11=""),"",(INT((A11-Settings!$B$6)/7)+1)*1E10+W11) | Y11: =IF(B11="","",IF(COUNTIF(B$5:B11,B11)=1,ROW(),"")) | Z11: =IF(H11="","",B11&"|"&E11) | AA11: =IF(B11="","",IF(COUNTIF(B11:B$1000,B11)=1,A11,""))
A12: 46288 | B12: My roommate's 3 rules | C12: Reddit Stories | D12: List / Countdown | E12: TikTok | F12: 47 | G12: 839 | H12: 1398 | I12: 0.55 | J12: 84 | K12: 11 | L12: 6 | M12: 3 | P12: =IF(F12="","",INDEX(Settings!$H$5:$H$9,1+(F12>15)+(F12>30)+(F12>45)+(F12>60))) | Q12: =IFERROR((J12+K12+L12)/H12,"") | R12: =IF(H12="","",IF(COUNTIFS(E:E,E12,P:P,P12,H:H,">=0")-1<3,"Need 3+",(SUMIFS(H:H,E:E,E12,P:P,P12)-H12)/(COUNTIFS(E:E,E12,P:P,P12,H:H,">=0")-1))) | S12: =IF(H12="","",IFERROR(ROUND(H12/R12,2),"—")) | T12: =IF(H12="","",IF(S12="—","—",IF(S12>=1.5,"🟢 Winner",IF(S12<=0.5,"🔴 Flop","Normal")))) | U12: =IF(I12="","",IF(I12>1,I12/100,I12)) | V12: =IF((COUNTIF(Settings!$D$5:$D$34,C12)+(C12=""))*(COUNTIF(Settings!$E$5:$E$34,D12)+(D12=""))*(COUNTIF(Settings!$F$5:$F$34,E12)+(E12="")),"","⚠ Not in Settings") | W12: =IF(H12="","",H12+ROW()/10000) | X12: =IF(OR(A12="",W12=""),"",(INT((A12-Settings!$B$6)/7)+1)*1E10+W12) | Y12: =IF(B12="","",IF(COUNTIF(B$5:B12,B12)=1,ROW(),"")) | Z12: =IF(H12="","",B12&"|"&E12) | AA12: =IF(B12="","",IF(COUNTIF(B12:B$1000,B12)=1,A12,""))
A13: 46288 | B13: My roommate's 3 rules | C13: Reddit Stories | D13: List / Countdown | E13: Instagram Reels | F13: 47 | G13: 313 | H13: 522 | I13: 0.5 | J13: 31 | K13: 4 | L13: 2 | M13: 1 | P13: =IF(F13="","",INDEX(Settings!$H$5:$H$9,1+(F13>15)+(F13>30)+(F13>45)+(F13>60))) | Q13: =IFERROR((J13+K13+L13)/H13,"") | R13: =IF(H13="","",IF(COUNTIFS(E:E,E13,P:P,P13,H:H,">=0")-1<3,"Need 3+",(SUMIFS(H:H,E:E,E13,P:P,P13)-H13)/(COUNTIFS(E:E,E13,P:P,P13,H:H,">=0")-1))) | S13: =IF(H13="","",IFERROR(ROUND(H13/R13,2),"—")) | T13: =IF(H13="","",IF(S13="—","—",IF(S13>=1.5,"🟢 Winner",IF(S13<=0.5,"🔴 Flop","Normal")))) | U13: =IF(I13="","",IF(I13>1,I13/100,I13)) | V13: =IF((COUNTIF(Settings!$D$5:$D$34,C13)+(C13=""))*(COUNTIF(Settings!$E$5:$E$34,D13)+(D13=""))*(COUNTIF(Settings!$F$5:$F$34,E13)+(E13="")),"","⚠ Not in Settings") | W13: =IF(H13="","",H13+ROW()/10000) | X13: =IF(OR(A13="",W13=""),"",(INT((A13-Settings!$B$6)/7)+1)*1E10+W13) | Y13: =IF(B13="","",IF(COUNTIF(B$5:B13,B13)=1,ROW(),"")) | Z13: =IF(H13="","",B13&"|"&E13) | AA13: =IF(B13="","",IF(COUNTIF(B13:B$1000,B13)=1,A13,""))
A14: 46289 | B14: My boss hit reply all | C14: Reddit Stories | D14: Story Cold Open | E14: YouTube Shorts | F14: 38 | G14: 708 | H14: 1180 | I14: 0.69 | J14: 71 | K14: 9 | L14: 5 | M14: 3 | P14: =IF(F14="","",INDEX(Settings!$H$5:$H$9,1+(F14>15)+(F14>30)+(F14>45)+(F14>60))) | Q14: =IFERROR((J14+K14+L14)/H14,"") | R14: =IF(H14="","",IF(COUNTIFS(E:E,E14,P:P,P14,H:H,">=0")-1<3,"Need 3+",(SUMIFS(H:H,E:E,E14,P:P,P14)-H14)/(COUNTIFS(E:E,E14,P:P,P14,H:H,">=0")-1))) | S14: =IF(H14="","",IFERROR(ROUND(H14/R14,2),"—")) | T14: =IF(H14="","",IF(S14="—","—",IF(S14>=1.5,"🟢 Winner",IF(S14<=0.5,"🔴 Flop","Normal")))) | U14: =IF(I14="","",IF(I14>1,I14/100,I14)) | V14: =IF((COUNTIF(Settings!$D$5:$D$34,C14)+(C14=""))*(COUNTIF(Settings!$E$5:$E$34,D14)+(D14=""))*(COUNTIF(Settings!$F$5:$F$34,E14)+(E14="")),"","⚠ Not in Settings") | W14: =IF(H14="","",H14+ROW()/10000) | X14: =IF(OR(A14="",W14=""),"",(INT((A14-Settings!$B$6)/7)+1)*1E10+W14) | Y14: =IF(B14="","",IF(COUNTIF(B$5:B14,B14)=1,ROW(),"")) | Z14: =IF(H14="","",B14&"|"&E14) | AA14: =IF(B14="","",IF(COUNTIF(B14:B$1000,B14)=1,A14,""))
A15: 46289 | B15: My boss hit reply all | C15: Reddit Stories | D15: Story Cold Open | E15: TikTok | F15: 38 | G15: 756 | H15: 1260 | I15: 0.66 | J15: 76 | K15: 10 | L15: 5 | M15: 3 | P15: =IF(F15="","",INDEX(Settings!$H$5:$H$9,1+(F15>15)+(F15>30)+(F15>45)+(F15>60))) | Q15: =IFERROR((J15+K15+L15)/H15,"") | R15: =IF(H15="","",IF(COUNTIFS(E:E,E15,P:P,P15,H:H,">=0")-1<3,"Need 3+",(SUMIFS(H:H,E:E,E15,P:P,P15)-H15)/(COUNTIFS(E:E,E15,P:P,P15,H:H,">=0")-1))) | S15: =IF(H15="","",IFERROR(ROUND(H15/R15,2),"—")) | T15: =IF(H15="","",IF(S15="—","—",IF(S15>=1.5,"🟢 Winner",IF(S15<=0.5,"🔴 Flop","Normal")))) | U15: =IF(I15="","",IF(I15>1,I15/100,I15)) | V15: =IF((COUNTIF(Settings!$D$5:$D$34,C15)+(C15=""))*(COUNTIF(Settings!$E$5:$E$34,D15)+(D15=""))*(COUNTIF(Settings!$F$5:$F$34,E15)+(E15="")),"","⚠ Not in Settings") | W15: =IF(H15="","",H15+ROW()/10000) | X15: =IF(OR(A15="",W15=""),"",(INT((A15-Settings!$B$6)/7)+1)*1E10+W15) | Y15: =IF(B15="","",IF(COUNTIF(B$5:B15,B15)=1,ROW(),"")) | Z15: =IF(H15="","",B15&"|"&E15) | AA15: =IF(B15="","",IF(COUNTIF(B15:B$1000,B15)=1,A15,""))
A16: 46289 | B16: My boss hit reply all | C16: Reddit Stories | D16: Story Cold Open | E16: Instagram Reels | F16: 38 | G16: 384 | H16: 640 | I16: 0.63 | J16: 38 | K16: 5 | L16: 3 | M16: 2 | P16: =IF(F16="","",INDEX(Settings!$H$5:$H$9,1+(F16>15)+(F16>30)+(F16>45)+(F16>60))) | Q16: =IFERROR((J16+K16+L16)/H16,"") | R16: =IF(H16="","",IF(COUNTIFS(E:E,E16,P:P,P16,H:H,">=0")-1<3,"Need 3+",(SUMIFS(H:H,E:E,E16,P:P,P16)-H16)/(COUNTIFS(E:E,E16,P:P,P16,H:H,">=0")-1))) | S16: =IF(H16="","",IFERROR(ROUND(H16/R16,2),"—")) | T16: =IF(H16="","",IF(S16="—","—",IF(S16>=1.5,"🟢 Winner",IF(S16<=0.5,"🔴 Flop","Normal")))) | U16: =IF(I16="","",IF(I16>1,I16/100,I16)) | V16: =IF((COUNTIF(Settings!$D$5:$D$34,C16)+(C16=""))*(COUNTIF(Settings!$E$5:$E$34,D16)+(D16=""))*(COUNTIF(Settings!$F$5:$F$34,E16)+(E16="")),"","⚠ Not in Settings") | W16: =IF(H16="","",H16+ROW()/10000) | X16: =IF(OR(A16="",W16=""),"",(INT((A16-Settings!$B$6)/7)+1)*1E10+W16) | Y16: =IF(B16="","",IF(COUNTIF(B$5:B16,B16)=1,ROW(),"")) | Z16: =IF(H16="","",B16&"|"&E16) | AA16: =IF(B16="","",IF(COUNTIF(B16:B$1000,B16)=1,A16,""))
A17: 46290 | B17: Can you see the Great Wall from space? | C17: History Facts | D17: Myth vs Truth | E17: YouTube Shorts | F17: 26 | G17: 588 | H17: 980 | I17: 0.8 | J17: 59 | K17: 8 | L17: 4 | M17: 2 | P17: =IF(F17="","",INDEX(Settings!$H$5:$H$9,1+(F17>15)+(F17>30)+(F17>45)+(F17>60))) | Q17: =IFERROR((J17+K17+L17)/H17,"") | R17: =IF(H17="","",IF(COUNTIFS(E:E,E17,P:P,P17,H:H,">=0")-1<3,"Need 3+",(SUMIFS(H:H,E:E,E17,P:P,P17)-H17)/(COUNTIFS(E:E,E17,P:P,P17,H:H,">=0")-1))) | S17: =IF(H17="","",IFERROR(ROUND(H17/R17,2),"—")) | T17: =IF(H17="","",IF(S17="—","—",IF(S17>=1.5,"🟢 Winner",IF(S17<=0.5,"🔴 Flop","Normal")))) | U17: =IF(I17="","",IF(I17>1,I17/100,I17)) | V17: =IF((COUNTIF(Settings!$D$5:$D$34,C17)+(C17=""))*(COUNTIF(Settings!$E$5:$E$34,D17)+(D17=""))*(COUNTIF(Settings!$F$5:$F$34,E17)+(E17="")),"","⚠ Not in Settings") | W17: =IF(H17="","",H17+ROW()/10000) | X17: =IF(OR(A17="",W17=""),"",(INT((A17-Settings!$B$6)/7)+1)*1E10+W17) | Y17: =IF(B17="","",IF(COUNTIF(B$5:B17,B17)=1,ROW(),"")) | Z17: =IF(H17="","",B17&"|"&E17) | AA17: =IF(B17="","",IF(COUNTIF(B17:B$1000,B17)=1,A17,""))
A18: 46290 | B18: Can you see the Great Wall from space? | C18: History Facts | D18: Myth vs Truth | E18: TikTok | F18: 26 | G18: 990 | H18: 1650 | I18: 0.77 | J18: 99 | K18: 13 | L18: 7 | M18: 4 | P18: =IF(F18="","",INDEX(Settings!$H$5:$H$9,1+(F18>15)+(F18>30)+(F18>45)+(F18>60))) | Q18: =IFERROR((J18+K18+L18)/H18,"") | R18: =IF(H18="","",IF(COUNTIFS(E:E,E18,P:P,P18,H:H,">=0")-1<3,"Need 3+",(SUMIFS(H:H,E:E,E18,P:P,P18)-H18)/(COUNTIFS(E:E,E18,P:P,P18,H:H,">=0")-1))) | S18: =IF(H18="","",IFERROR(ROUND(H18/R18,2),"—")) | T18: =IF(H18="","",IF(S18="—","—",IF(S18>=1.5,"🟢 Winner",IF(S18<=0.5,"🔴 Flop","Normal")))) | U18: =IF(I18="","",IF(I18>1,I18/100,I18)) | V18: =IF((COUNTIF(Settings!$D$5:$D$34,C18)+(C18=""))*(COUNTIF(Settings!$E$5:$E$34,D18)+(D18=""))*(COUNTIF(Settings!$F$5:$F$34,E18)+(E18="")),"","⚠ Not in Settings") | W18: =IF(H18="","",H18+ROW()/10000) | X18: =IF(OR(A18="",W18=""),"",(INT((A18-Settings!$B$6)/7)+1)*1E10+W18) | Y18: =IF(B18="","",IF(COUNTIF(B$5:B18,B18)=1,ROW(),"")) | Z18: =IF(H18="","",B18&"|"&E18) | AA18: =IF(B18="","",IF(COUNTIF(B18:B$1000,B18)=1,A18,""))
... A25: 46293 | B25: Napoleon wasn't short | C25: History Facts | D25: Myth vs Truth | E25: Instagram Reels | F25: 24 | G25: 744 | H25: 1240 | I25: 0.78 | J25: 74 | K25: 10 | L25: 5 | M25: 3 | P25: =IF(F25="","",INDEX(Settings!$H$5:$H$9,1+(F25>15)+(F25>30)+(F25>45)+(F25>60))) | Q25: =IFERROR((J25+K25+L25)/H25,"") | R25: =IF(H25="","",IF(COUNTIFS(E:E,E25,P:P,P25,H:H,">=0")-1<3,"Need 3+",(SUMIFS(H:H,E:E,E25,P:P,P25)-H25)/(COUNTIFS(E:E,E25,P:P,P25,H:H,">=0")-1))) | S25: =IF(H25="","",IFERROR(ROUND(H25/R25,2),"—")) | T25: =IF(H25="","",IF(S25="—","—",IF(S25>=1.5,"🟢 Winner",IF(S25<=0.5,"🔴 Flop","Normal")))) | U25: =IF(I25="","",IF(I25>1,I25/100,I25)) | V25: =IF((COUNTIF(Settings!$D$5:$D$34,C25)+(C25=""))*(COUNTIF(Settings!$E$5:$E$34,D25)+(D25=""))*(COUNTIF(Settings!$F$5:$F$34,E25)+(E25="")),"","⚠ Not in Settings") | W25: =IF(H25="","",H25+ROW()/10000) | X25: =IF(OR(A25="",W25=""),"",(INT((A25-Settings!$B$6)/7)+1)*1E10+W25) | Y25: =IF(B25="","",IF(COUNTIF(B$5:B25,B25)=1,ROW(),"")) | Z25: =IF(H25="","",B25&"|"&E25) | AA25: =IF(B25="","",IF(COUNTIF(B25:B$1000,B25)=1,A25,""))
A26: 46294 | B26: The 38-minute war | C26: History Facts | D26: Shocking Fact | E26: YouTube Shorts | F26: 27 | G26: 1740 | H26: 2900 | I26: 0.82 | J26: 174 | K26: 23 | L26: 12 | M26: 7 | N26: 15 | O26: 6 | P26: =IF(F26="","",INDEX(Settings!$H$5:$H$9,1+(F26>15)+(F26>30)+(F26>45)+(F26>60))) | Q26: =IFERROR((J26+K26+L26)/H26,"") | R26: =IF(H26="","",IF(COUNTIFS(E:E,E26,P:P,P26,H:H,">=0")-1<3,"Need 3+",(SUMIFS(H:H,E:E,E26,P:P,P26)-H26)/(COUNTIFS(E:E,E26,P:P,P26,H:H,">=0")-1))) | S26: =IF(H26="","",IFERROR(ROUND(H26/R26,2),"—")) | T26: =IF(H26="","",IF(S26="—","—",IF(S26>=1.5,"🟢 Winner",IF(S26<=0.5,"🔴 Flop","Normal")))) | U26: =IF(I26="","",IF(I26>1,I26/100,I26)) | V26: =IF((COUNTIF(Settings!$D$5:$D$34,C26)+(C26=""))*(COUNTIF(Settings!$E$5:$E$34,D26)+(D26=""))*(COUNTIF(Settings!$F$5:$F$34,E26)+(E26="")),"","⚠ Not in Settings") | W26: =IF(H26="","",H26+ROW()/10000) | X26: =IF(OR(A26="",W26=""),"",(INT((A26-Settings!$B$6)/7)+1)*1E10+W26) | Y26: =IF(B26="","",IF(COUNTIF(B$5:B26,B26)=1,ROW(),"")) | Z26: =IF(H26="","",B26&"|"&E26) | AA26: =IF(B26="","",IF(COUNTIF(B26:B$1000,B26)=1,A26,""))
A27: 46294 | B27: The 38-minute war | C27: History Facts | D27: Shocking Fact | E27: TikTok | F27: 27 | G27: 600 | H27: 1000 | I27: 0.71 | J27: 60 | K27: 8 | L27: 4 | M27: 3 | P27: =IF(F27="","",INDEX(Settings!$H$5:$H$9,1+(F27>15)+(F27>30)+(F27>45)+(F27>60))) | Q27: =IFERROR((J27+K27+L27)/H27,"") | R27: =IF(H27="","",IF(COUNTIFS(E:E,E27,P:P,P27,H:H,">=0")-1<3,"Need 3+",(SUMIFS(H:H,E:E,E27,P:P,P27)-H27)/(COUNTIFS(E:E,E27,P:P,P27,H:H,">=0")-1))) | S27: =IF(H27="","",IFERROR(ROUND(H27/R27,2),"—")) | T27: =IF(H27="","",IF(S27="—","—",IF(S27>=1.5,"🟢 Winner",IF(S27<=0.5,"🔴 Flop","Normal")))) | U27: =IF(I27="","",IF(I27>1,I27/100,I27)) | V27: =IF((COUNTIF(Settings!$D$5:$D$34,C27)+(C27=""))*(COUNTIF(Settings!$E$5:$E$34,D27)+(D27=""))*(COUNTIF(Settings!$F$5:$F$34,E27)+(E27="")),"","⚠ Not in Settings") | W27: =IF(H27="","",H27+ROW()/10000) | X27: =IF(OR(A27="",W27=""),"",(INT((A27-Settings!$B$6)/7)+1)*1E10+W27) | Y27: =IF(B27="","",IF(COUNTIF(B$5:B27,B27)=1,ROW(),"")) | Z27: =IF(H27="","",B27&"|"&E27) | AA27: =IF(B27="","",IF(COUNTIF(B27:B$1000,B27)=1,A27,""))
A28: 46294 | B28: The 38-minute war | C28: History Facts | D28: Shocking Fact | E28: Instagram Reels | F28: 27 | G28: 528 | H28: 880 | I28: 0.76 | J28: 53 | K28: 7 | L28: 4 | M28: 2 | P28: =IF(F28="","",INDEX(Settings!$H$5:$H$9,1+(F28>15)+(F28>30)+(F28>45)+(F28>60))) | Q28: =IFERROR((J28+K28+L28)/H28,"") | R28: =IF(H28="","",IF(COUNTIFS(E:E,E28,P:P,P28,H:H,">=0")-1<3,"Need 3+",(SUMIFS(H:H,E:E,E28,P:P,P28)-H28)/(COUNTIFS(E:E,E28,P:P,P28,H:H,">=0")-1))) | S28: =IF(H28="","",IFERROR(ROUND(H28/R28,2),"—")) | T28: =IF(H28="","",IF(S28="—","—",IF(S28>=1.5,"🟢 Winner",IF(S28<=0.5,"🔴 Flop","Normal")))) | U28: =IF(I28="","",IF(I28>1,I28/100,I28)) | V28: =IF((COUNTIF(Settings!$D$5:$D$34,C28)+(C28=""))*(COUNTIF(Settings!$E$5:$E$34,D28)+(D28=""))*(COUNTIF(Settings!$F$5:$F$34,E28)+(E28="")),"","⚠ Not in Settings") | W28: =IF(H28="","",H28+ROW()/10000) | X28: =IF(OR(A28="",W28=""),"",(INT((A28-Settings!$B$6)/7)+1)*1E10+W28) | Y28: =IF(B28="","",IF(COUNTIF(B$5:B28,B28)=1,ROW(),"")) | Z28: =IF(H28="","",B28&"|"&E28) | AA28: =IF(B28="","",IF(COUNTIF(B28:B$1000,B28)=1,A28,""))
A29: 46295 | B29: The wedding gift receipt | C29: Reddit Stories | D29: Question | E29: YouTube Shorts | F29: 43 | G29: 1134 | H29: 1890 | I29: 0.7 | J29: 113 | K29: 15 | L29: 8 | M29: 5 | P29: =IF(F29="","",INDEX(Settings!$H$5:$H$9,1+(F29>15)+(F29>30)+(F29>45)+(F29>60))) | Q29: =IFERROR((J29+K29+L29)/H29,"") | R29: =IF(H29="","",IF(COUNTIFS(E:E,E29,P:P,P29,H:H,">=0")-1<3,"Need 3+",(SUMIFS(H:H,E:E,E29,P:P,P29)-H29)/(COUNTIFS(E:E,E29,P:P,P29,H:H,">=0")-1))) | S29: =IF(H29="","",IFERROR(ROUND(H29/R29,2),"—")) | T29: =IF(H29="","",IF(S29="—","—",IF(S29>=1.5,"🟢 Winner",IF(S29<=0.5,"🔴 Flop","Normal")))) | U29: =IF(I29="","",IF(I29>1,I29/100,I29)) | V29: =IF((COUNTIF(Settings!$D$5:$D$34,C29)+(C29=""))*(COUNTIF(Settings!$E$5:$E$34,D29)+(D29=""))*(COUNTIF(Settings!$F$5:$F$34,E29)+(E29="")),"","⚠ Not in Settings") | W29: =IF(H29="","",H29+ROW()/10000) | X29: =IF(OR(A29="",W29=""),"",(INT((A29-Settings!$B$6)/7)+1)*1E10+W29) | Y29: =IF(B29="","",IF(COUNTIF(B$5:B29,B29)=1,ROW(),"")) | Z29: =IF(H29="","",B29&"|"&E29) | AA29: =IF(B29="","",IF(COUNTIF(B29:B$1000,B29)=1,A29,""))
A30: 46295 | B30: The wedding gift receipt | C30: Reddit Stories | D30: Question | E30: TikTok | F30: 43 | G30: 1110 | H30: 1850 | I30: 0.68 | J30: 111 | K30: 15 | L30: 7 | M30: 5 | P30: =IF(F30="","",INDEX(Settings!$H$5:$H$9,1+(F30>15)+(F30>30)+(F30>45)+(F30>60))) | Q30: =IFERROR((J30+K30+L30)/H30,"") | R30: =IF(H30="","",IF(COUNTIFS(E:E,E30,P:P,P30,H:H,">=0")-1<3,"Need 3+",(SUMIFS(H:H,E:E,E30,P:P,P30)-H30)/(COUNTIFS(E:E,E30,P:P,P30,H:H,">=0")-1))) | S30: =IF(H30="","",IFERROR(ROUND(H30/R30,2),"—")) | T30: =IF(H30="","",IF(S30="—","—",IF(S30>=1.5,"🟢 Winner",IF(S30<=0.5,"🔴 Flop","Normal")))) | U30: =IF(I30="","",IF(I30>1,I30/100,I30)) | V30: =IF((COUNTIF(Settings!$D$5:$D$34,C30)+(C30=""))*(COUNTIF(Settings!$E$5:$E$34,D30)+(D30=""))*(COUNTIF(Settings!$F$5:$F$34,E30)+(E30="")),"","⚠ Not in Settings") | W30: =IF(H30="","",H30+ROW()/10000) | X30: =IF(OR(A30="",W30=""),"",(INT((A30-Settings!$B$6)/7)+1)*1E10+W30) | Y30: =IF(B30="","",IF(COUNTIF(B$5:B30,B30)=1,ROW(),"")) | Z30: =IF(H30="","",B30&"|"&E30) | AA30: =IF(B30="","",IF(COUNTIF(B30:B$1000,B30)=1,A30,""))
A31: 46295 | B31: The wedding gift receipt | C31: Reddit Stories | D31: Question | E31: Instagram Reels | F31: 43 | G31: 726 | H31: 1210 | I31: 0.65 | J31: 73 | K31: 10 | L31: 5 | M31: 3 | P31: =IF(F31="","",INDEX(Settings!$H$5:$H$9,1+(F31>15)+(F31>30)+(F31>45)+(F31>60))) | Q31: =IFERROR((J31+K31+L31)/H31,"") | R31: =IF(H31="","",IF(COUNTIFS(E:E,E31,P:P,P31,H:H,">=0")-1<3,"Need 3+",(SUMIFS(H:H,E:E,E31,P:P,P31)-H31)/(COUNTIFS(E:E,E31,P:P,P31,H:H,">=0")-1))) | S31: =IF(H31="","",IFERROR(ROUND(H31/R31,2),"—")) | T31: =IF(H31="","",IF(S31="—","—",IF(S31>=1.5,"🟢 Winner",IF(S31<=0.5,"🔴 Flop","Normal")))) | U31: =IF(I31="","",IF(I31>1,I31/100,I31)) | V31: =IF((COUNTIF(Settings!$D$5:$D$34,C31)+(C31=""))*(COUNTIF(Settings!$E$5:$E$34,D31)+(D31=""))*(COUNTIF(Settings!$F$5:$F$34,E31)+(E31="")),"","⚠ Not in Settings") | W31: =IF(H31="","",H31+ROW()/10000) | X31: =IF(OR(A31="",W31=""),"",(INT((A31-Settings!$B$6)/7)+1)*1E10+W31) | Y31: =IF(B31="","",IF(COUNTIF(B$5:B31,B31)=1,ROW(),"")) | Z31: =IF(H31="","",B31&"|"&E31) | AA31: =IF(B31="","",IF(COUNTIF(B31:B$1000,B31)=1,A31,""))
A32: 46296 | B32: The Great Emu War | C32: History Facts | D32: You won't believe | E32: YouTube Shorts | F32: 24 | G32: 690 | H32: 1150 | I32: 0.85 | J32: 69 | K32: 9 | L32: 5 | M32: 3 | P32: =IF(F32="","",INDEX(Settings!$H$5:$H$9,1+(F32>15)+(F32>30)+(F32>45)+(F32>60))) | Q32: =IFERROR((J32+K32+L32)/H32,"") | R32: =IF(H32="","",IF(COUNTIFS(E:E,E32,P:P,P32,H:H,">=0")-1<3,"Need 3+",(SUMIFS(H:H,E:E,E32,P:P,P32)-H32)/(COUNTIFS(E:E,E32,P:P,P32,H:H,">=0")-1))) | S32: =IF(H32="","",IFERROR(ROUND(H32/R32,2),"—")) | T32: =IF(H32="","",IF(S32="—","—",IF(S32>=1.5,"🟢 Winner",IF(S32<=0.5,"🔴 Flop","Normal")))) | U32: =IF(I32="","",IF(I32>1,I32/100,I32)) | V32: =IF((COUNTIF(Settings!$D$5:$D$34,C32)+(C32=""))*(COUNTIF(Settings!$E$5:$E$34,D32)+(D32=""))*(COUNTIF(Settings!$F$5:$F$34,E32)+(E32="")),"","⚠ Not in Settings") | W32: =IF(H32="","",H32+ROW()/10000) | X32: =IF(OR(A32="",W32=""),"",(INT((A32-Settings!$B$6)/7)+1)*1E10+W32) | Y32: =IF(B32="","",IF(COUNTIF(B$5:B32,B32)=1,ROW(),"")) | Z32: =IF(H32="","",B32&"|"&E32) | AA32: =IF(B32="","",IF(COUNTIF(B32:B$1000,B32)=1,A32,""))
A33: 46296 | B33: The Great Emu War | C33: History Facts | D33: You won't believe | E33: TikTok | F33: 24 | G33: 2880 | H33: 4800 | I33: 0.88 | J33: 288 | K33: 38 | L33: 19 | M33: 12 | N33: 22 | O33: 8.8 | P33: =IF(F33="","",INDEX(Settings!$H$5:$H$9,1+(F33>15)+(F33>30)+(F33>45)+(F33>60))) | Q33: =IFERROR((J33+K33+L33)/H33,"") | R33: =IF(H33="","",IF(COUNTIFS(E:E,E33,P:P,P33,H:H,">=0")-1<3,"Need 3+",(SUMIFS(H:H,E:E,E33,P:P,P33)-H33)/(COUNTIFS(E:E,E33,P:P,P33,H:H,">=0")-1))) | S33: =IF(H33="","",IFERROR(ROUND(H33/R33,2),"—")) | T33: =IF(H33="","",IF(S33="—","—",IF(S33>=1.5,"🟢 Winner",IF(S33<=0.5,"🔴 Flop","Normal")))) | U33: =IF(I33="","",IF(I33>1,I33/100,I33)) | V33: =IF((COUNTIF(Settings!$D$5:$D$34,C33)+(C33=""))*(COUNTIF(Settings!$E$5:$E$34,D33)+(D33=""))*(COUNTIF(Settings!$F$5:$F$34,E33)+(E33="")),"","⚠ Not in Settings") | W33: =IF(H33="","",H33+ROW()/10000) | X33: =IF(OR(A33="",W33=""),"",(INT((A33-Settings!$B$6)/7)+1)*1E10+W33) | Y33: =IF(B33="","",IF(COUNTIF(B$5:B33,B33)=1,ROW(),"")) | Z33: =IF(H33="","",B33&"|"&E33) | AA33: =IF(B33="","",IF(COUNTIF(B33:B$1000,B33)=1,A33,""))
A34: 46296 | B34: The Great Emu War | C34: History Facts | D34: You won't believe | E34: Instagram Reels | F34: 24 | G34: 978 | H34: 1630 | I34: 0.83 | J34: 98 | K34: 13 | L34: 7 | M34: 4 | P34: =IF(F34="","",INDEX(Settings!$H$5:$H$9,1+(F34>15)+(F34>30)+(F34>45)+(F34>60))) | Q34: =IFERROR((J34+K34+L34)/H34,"") | R34: =IF(H34="","",IF(COUNTIFS(E:E,E34,P:P,P34,H:H,">=0")-1<3,"Need 3+",(SUMIFS(H:H,E:E,E34,P:P,P34)-H34)/(COUNTIFS(E:E,E34,P:P,P34,H:H,">=0")-1))) | S34: =IF(H34="","",IFERROR(ROUND(H34/R34,2),"—")) | T34: =IF(H34="","",IF(S34="—","—",IF(S34>=1.5,"🟢 Winner",IF(S34<=0.5,"🔴 Flop","Normal")))) | U34: =IF(I34="","",IF(I34>1,I34/100,I34)) | V34: =IF((COUNTIF(Settings!$D$5:$D$34,C34)+(C34=""))*(COUNTIF(Settings!$E$5:$E$34,D34)+(D34=""))*(COUNTIF(Settings!$F$5:$F$34,E34)+(E34="")),"","⚠ Not in Settings") | W34: =IF(H34="","",H34+ROW()/10000) | X34: =IF(OR(A34="",W34=""),"",(INT((A34-Settings!$B$6)/7)+1)*1E10+W34) | Y34: =IF(B34="","",IF(COUNTIF(B$5:B34,B34)=1,ROW(),"")) | Z34: =IF(H34="","",B34&"|"&E34) | AA34: =IF(B34="","",IF(COUNTIF(B34:B$1000,B34)=1,A34,""))
A35: 46297 | B35: 3 red flags at my first apartment viewing | C35: Reddit Stories | D35: List / Countdown | E35: YouTube Shorts | F35: 36 | G35: 336 | H35: 560 | I35: 0.57 | J35: 34 | K35: 4 | L35: 2 | M35: 1 | P35: =IF(F35="","",INDEX(Settings!$H$5:$H$9,1+(F35>15)+(F35>30)+(F35>45)+(F35>60))) | Q35: =IFERROR((J35+K35+L35)/H35,"") | R35: =IF(H35="","",IF(COUNTIFS(E:E,E35,P:P,P35,H:H,">=0")-1<3,"Need 3+",(SUMIFS(H:H,E:E,E35,P:P,P35)-H35)/(COUNTIFS(E:E,E35,P:P,P35,H:H,">=0")-1))) | S35: =IF(H35="","",IFERROR(ROUND(H35/R35,2),"—")) | T35: =IF(H35="","",IF(S35="—","—",IF(S35>=1.5,"🟢 Winner",IF(S35<=0.5,"🔴 Flop","Normal")))) | U35: =IF(I35="","",IF(I35>1,I35/100,I35)) | V35: =IF((COUNTIF(Settings!$D$5:$D$34,C35)+(C35=""))*(COUNTIF(Settings!$E$5:$E$34,D35)+(D35=""))*(COUNTIF(Settings!$F$5:$F$34,E35)+(E35="")),"","⚠ Not in Settings") | W35: =IF(H35="","",H35+ROW()/10000) | X35: =IF(OR(A35="",W35=""),"",(INT((A35-Settings!$B$6)/7)+1)*1E10+W35) | Y35: =IF(B35="","",IF(COUNTIF(B$5:B35,B35)=1,ROW(),"")) | Z35: =IF(H35="","",B35&"|"&E35) | AA35: =IF(B35="","",IF(COUNTIF(B35:B$1000,B35)=1,A35,""))
A36: 46297 | B36: 3 red flags at my first apartment viewing | C36: Reddit Stories | D36: List / Countdown | E36: TikTok | F36: 36 | G36: 540 | H36: 900 | I36: 0.54 | J36: 54 | K36: 7 | L36: 4 | M36: 2 | P36: =IF(F36="","",INDEX(Settings!$H$5:$H$9,1+(F36>15)+(F36>30)+(F36>45)+(F36>60))) | Q36: =IFERROR((J36+K36+L36)/H36,"") | R36: =IF(H36="","",IF(COUNTIFS(E:E,E36,P:P,P36,H:H,">=0")-1<3,"Need 3+",(SUMIFS(H:H,E:E,E36,P:P,P36)-H36)/(COUNTIFS(E:E,E36,P:P,P36,H:H,">=0")-1))) | S36: =IF(H36="","",IFERROR(ROUND(H36/R36,2),"—")) | T36: =IF(H36="","",IF(S36="—","—",IF(S36>=1.5,"🟢 Winner",IF(S36<=0.5,"🔴 Flop","Normal")))) | U36: =IF(I36="","",IF(I36>1,I36/100,I36)) | V36: =IF((COUNTIF(Settings!$D$5:$D$34,C36)+(C36=""))*(COUNTIF(Settings!$E$5:$E$34,D36)+(D36=""))*(COUNTIF(Settings!$F$5:$F$34,E36)+(E36="")),"","⚠ Not in Settings") | W36: =IF(H36="","",H36+ROW()/10000) | X36: =IF(OR(A36="",W36=""),"",(INT((A36-Settings!$B$6)/7)+1)*1E10+W36) | Y36: =IF(B36="","",IF(COUNTIF(B$5:B36,B36)=1,ROW(),"")) | Z36: =IF(H36="","",B36&"|"&E36) | AA36: =IF(B36="","",IF(COUNTIF(B36:B$1000,B36)=1,A36,""))
A37: 46297 | B37: 3 red flags at my first apartment viewing | C37: Reddit Stories | D37: List / Countdown | E37: Instagram Reels | F37: 36 | G37: 228 | H37: 380 | I37: 0.45 | J37: 23 | K37: 3 | L37: 2 | M37: 1 | P37: =IF(F37="","",INDEX(Settings!$H$5:$H$9,1+(F37>15)+(F37>30)+(F37>45)+(F37>60))) | Q37: =IFERROR((J37+K37+L37)/H37,"") | R37: =IF(H37="","",IF(COUNTIFS(E:E,E37,P:P,P37,H:H,">=0")-1<3,"Need 3+",(SUMIFS(H:H,E:E,E37,P:P,P37)-H37)/(COUNTIFS(E:E,E37,P:P,P37,H:H,">=0")-1))) | S37: =IF(H37="","",IFERROR(ROUND(H37/R37,2),"—")) | T37: =IF(H37="","",IF(S37="—","—",IF(S37>=1.5,"🟢 Winner",IF(S37<=0.5,"🔴 Flop","Normal")))) | U37: =IF(I37="","",IF(I37>1,I37/100,I37)) | V37: =IF((COUNTIF(Settings!$D$5:$D$34,C37)+(C37=""))*(COUNTIF(Settings!$E$5:$E$34,D37)+(D37=""))*(COUNTIF(Settings!$F$5:$F$34,E37)+(E37="")),"","⚠ Not in Settings") | W37: =IF(H37="","",H37+ROW()/10000) | X37: =IF(OR(A37="",W37=""),"",(INT((A37-Settings!$B$6)/7)+1)*1E10+W37) | Y37: =IF(B37="","",IF(COUNTIF(B$5:B37,B37)=1,ROW(),"")) | Z37: =IF(H37="","",B37&"|"&E37) | AA37: =IF(B37="","",IF(COUNTIF(B37:B$1000,B37)=1,A37,""))
A38: 46298 | B38: Cleopatra lived closer to the Moon landing | C38: History Facts | D38: You won't believe | E38: YouTube Shorts | F38: 29 | G38: 852 | H38: 1420 | I38: 0.81 | J38: 85 | K38: 11 | L38: 6 | M38: 4 | P38: =IF(F38="","",INDEX(Settings!$H$5:$H$9,1+(F38>15)+(F38>30)+(F38>45)+(F38>60))) | Q38: =IFERROR((J38+K38+L38)/H38,"") | R38: =IF(H38="","",IF(COUNTIFS(E:E,E38,P:P,P38,H:H,">=0")-1<3,"Need 3+",(SUMIFS(H:H,E:E,E38,P:P,P38)-H38)/(COUNTIFS(E:E,E38,P:P,P38,H:H,">=0")-1))) | S38: =IF(H38="","",IFERROR(ROUND(H38/R38,2),"—")) | T38: =IF(H38="","",IF(S38="—","—",IF(S38>=1.5,"🟢 Winner",IF(S38<=0.5,"🔴 Flop","Normal")))) | U38: =IF(I38="","",IF(I38>1,I38/100,I38)) | V38: =IF((COUNTIF(Settings!$D$5:$D$34,C38)+(C38=""))*(COUNTIF(Settings!$E$5:$E$34,D38)+(D38=""))*(COUNTIF(Settings!$F$5:$F$34,E38)+(E38="")),"","⚠ Not in Settings") | W38: =IF(H38="","",H38+ROW()/10000) | X38: =IF(OR(A38="",W38=""),"",(INT((A38-Settings!$B$6)/7)+1)*1E10+W38) | Y38: =IF(B38="","",IF(COUNTIF(B$5:B38,B38)=1,ROW(),"")) | Z38: =IF(H38="","",B38&"|"&E38) | AA38: =IF(B38="","",IF(COUNTIF(B38:B$1000,B38)=1,A38,""))
A39: 46298 | B39: Cleopatra lived closer to the Moon landing | C39: History Facts | D39: You won't believe | E39: TikTok | F39: 29 | G39: 1410 | H39: 2350 | I39: 0.8 | J39: 141 | K39: 19 | L39: 9 | M39: 6 | P39: =IF(F39="","",INDEX(Settings!$H$5:$H$9,1+(F39>15)+(F39>30)+(F39>45)+(F39>60))) | Q39: =IFERROR((J39+K39+L39)/H39,"") | R39: =IF(H39="","",IF(COUNTIFS(E:E,E39,P:P,P39,H:H,">=0")-1<3,"Need 3+",(SUMIFS(H:H,E:E,E39,P:P,P39)-H39)/(COUNTIFS(E:E,E39,P:P,P39,H:H,">=0")-1))) | S39: =IF(H39="","",IFERROR(ROUND(H39/R39,2),"—")) | T39: =IF(H39="","",IF(S39="—","—",IF(S39>=1.5,"🟢 Winner",IF(S39<=0.5,"🔴 Flop","Normal")))) | U39: =IF(I39="","",IF(I39>1,I39/100,I39)) | V39: =IF((COUNTIF(Settings!$D$5:$D$34,C39)+(C39=""))*(COUNTIF(Settings!$E$5:$E$34,D39)+(D39=""))*(COUNTIF(Settings!$F$5:$F$34,E39)+(E39="")),"","⚠ Not in Settings") | W39: =IF(H39="","",H39+ROW()/10000) | X39: =IF(OR(A39="",W39=""),"",(INT((A39-Settings!$B$6)/7)+1)*1E10+W39) | Y39: =IF(B39="","",IF(COUNTIF(B$5:B39,B39)=1,ROW(),"")) | Z39: =IF(H39="","",B39&"|"&E39) | AA39: =IF(B39="","",IF(COUNTIF(B39:B$1000,B39)=1,A39,""))
A40: 46298 | B40: Cleopatra lived closer to the Moon landing | C40: History Facts | D40: You won't believe | E40: Instagram Reels | F40: 29 | G40: 540 | H40: 900 | I40: 0.74 | J40: 54 | K40: 7 | L40: 4 | M40: 2 | P40: =IF(F40="","",INDEX(Settings!$H$5:$H$9,1+(F40>15)+(F40>30)+(F40>45)+(F40>60))) | Q40: =IFERROR((J40+K40+L40)/H40,"") | R40: =IF(H40="","",IF(COUNTIFS(E:E,E40,P:P,P40,H:H,">=0")-1<3,"Need 3+",(SUMIFS(H:H,E:E,E40,P:P,P40)-H40)/(COUNTIFS(E:E,E40,P:P,P40,H:H,">=0")-1))) | S40: =IF(H40="","",IFERROR(ROUND(H40/R40,2),"—")) | T40: =IF(H40="","",IF(S40="—","—",IF(S40>=1.5,"🟢 Winner",IF(S40<=0.5,"🔴 Flop","Normal")))) | U40: =IF(I40="","",IF(I40>1,I40/100,I40)) | V40: =IF((COUNTIF(Settings!$D$5:$D$34,C40)+(C40=""))*(COUNTIF(Settings!$E$5:$E$34,D40)+(D40=""))*(COUNTIF(Settings!$F$5:$F$34,E40)+(E40="")),"","⚠ Not in Settings") | W40: =IF(H40="","",H40+ROW()/10000) | X40: =IF(OR(A40="",W40=""),"",(INT((A40-Settings!$B$6)/7)+1)*1E10+W40) | Y40: =IF(B40="","",IF(COUNTIF(B$5:B40,B40)=1,ROW(),"")) | Z40: =IF(H40="","",B40&"|"&E40) | AA40: =IF(B40="","",IF(COUNTIF(B40:B$1000,B40)=1,A40,""))
P41: =IF(F41="","",INDEX(Settings!$H$5:$H$9,1+(F41>15)+(F41>30)+(F41>45)+(F41>60))) | Q41: =IFERROR((J41+K41+L41)/H41,"") | R41: =IF(H41="","",IF(COUNTIFS(E:E,E41,P:P,P41,H:H,">=0")-1<3,"Need 3+",(SUMIFS(H:H,E:E,E41,P:P,P41)-H41)/(COUNTIFS(E:E,E41,P:P,P41,H:H,">=0")-1))) | S41: =IF(H41="","",IFERROR(ROUND(H41/R41,2),"—")) | T41: =IF(H41="","",IF(S41="—","—",IF(S41>=1.5,"🟢 Winner",IF(S41<=0.5,"🔴 Flop","Normal")))) | U41: =IF(I41="","",IF(I41>1,I41/100,I41)) | V41: =IF((COUNTIF(Settings!$D$5:$D$34,C41)+(C41=""))*(COUNTIF(Settings!$E$5:$E$34,D41)+(D41=""))*(COUNTIF(Settings!$F$5:$F$34,E41)+(E41="")),"","⚠ Not in Settings") | W41: =IF(H41="","",H41+ROW()/10000) | X41: =IF(OR(A41="",W41=""),"",(INT((A41-Settings!$B$6)/7)+1)*1E10+W41) | Y41: =IF(B41="","",IF(COUNTIF(B$5:B41,B41)=1,ROW(),"")) | Z41: =IF(H41="","",B41&"|"&E41) | AA41: =IF(B41="","",IF(COUNTIF(B41:B$1000,B41)=1,A41,""))
P42: =IF(F42="","",INDEX(Settings!$H$5:$H$9,1+(F42>15)+(F42>30)+(F42>45)+(F42>60))) | Q42: =IFERROR((J42+K42+L42)/H42,"") | R42: =IF(H42="","",IF(COUNTIFS(E:E,E42,P:P,P42,H:H,">=0")-1<3,"Need 3+",(SUMIFS(H:H,E:E,E42,P:P,P42)-H42)/(COUNTIFS(E:E,E42,P:P,P42,H:H,">=0")-1))) | S42: =IF(H42="","",IFERROR(ROUND(H42/R42,2),"—")) | T42: =IF(H42="","",IF(S42="—","—",IF(S42>=1.5,"🟢 Winner",IF(S42<=0.5,"🔴 Flop","Normal")))) | U42: =IF(I42="","",IF(I42>1,I42/100,I42)) | V42: =IF((COUNTIF(Settings!$D$5:$D$34,C42)+(C42=""))*(COUNTIF(Settings!$E$5:$E$34,D42)+(D42=""))*(COUNTIF(Settings!$F$5:$F$34,E42)+(E42="")),"","⚠ Not in Settings") | W42: =IF(H42="","",H42+ROW()/10000) | X42: =IF(OR(A42="",W42=""),"",(INT((A42-Settings!$B$6)/7)+1)*1E10+W42) | Y42: =IF(B42="","",IF(COUNTIF(B$5:B42,B42)=1,ROW(),"")) | Z42: =IF(H42="","",B42&"|"&E42) | AA42: =IF(B42="","",IF(COUNTIF(B42:B$1000,B42)=1,A42,""))
P43: =IF(F43="","",INDEX(Settings!$H$5:$H$9,1+(F43>15)+(F43>30)+(F43>45)+(F43>60))) | Q43: =IFERROR((J43+K43+L43)/H43,"") | R43: =IF(H43="","",IF(COUNTIFS(E:E,E43,P:P,P43,H:H,">=0")-1<3,"Need 3+",(SUMIFS(H:H,E:E,E43,P:P,P43)-H43)/(COUNTIFS(E:E,E43,P:P,P43,H:H,">=0")-1))) | S43: =IF(H43="","",IFERROR(ROUND(H43/R43,2),"—")) | T43: =IF(H43="","",IF(S43="—","—",IF(S43>=1.5,"🟢 Winner",IF(S43<=0.5,"🔴 Flop","Normal")))) | U43: =IF(I43="","",IF(I43>1,I43/100,I43)) | V43: =IF((COUNTIF(Settings!$D$5:$D$34,C43)+(C43=""))*(COUNTIF(Settings!$E$5:$E$34,D43)+(D43=""))*(COUNTIF(Settings!$F$5:$F$34,E43)+(E43="")),"","⚠ Not in Settings") | W43: =IF(H43="","",H43+ROW()/10000) | X43: =IF(OR(A43="",W43=""),"",(INT((A43-Settings!$B$6)/7)+1)*1E10+W43) | Y43: =IF(B43="","",IF(COUNTIF(B$5:B43,B43)=1,ROW(),"")) | Z43: =IF(H43="","",B43&"|"&E43) | AA43: =IF(B43="","",IF(COUNTIF(B43:B$1000,B43)=1,A43,""))
P44: =IF(F44="","",INDEX(Settings!$H$5:$H$9,1+(F44>15)+(F44>30)+(F44>45)+(F44>60))) | Q44: =IFERROR((J44+K44+L44)/H44,"") | R44: =IF(H44="","",IF(COUNTIFS(E:E,E44,P:P,P44,H:H,">=0")-1<3,"Need 3+",(SUMIFS(H:H,E:E,E44,P:P,P44)-H44)/(COUNTIFS(E:E,E44,P:P,P44,H:H,">=0")-1))) | S44: =IF(H44="","",IFERROR(ROUND(H44/R44,2),"—")) | T44: =IF(H44="","",IF(S44="—","—",IF(S44>=1.5,"🟢 Winner",IF(S44<=0.5,"🔴 Flop","Normal")))) | U44: =IF(I44="","",IF(I44>1,I44/100,I44)) | V44: =IF((COUNTIF(Settings!$D$5:$D$34,C44)+(C44=""))*(COUNTIF(Settings!$E$5:$E$34,D44)+(D44=""))*(COUNTIF(Settings!$F$5:$F$34,E44)+(E44="")),"","⚠ Not in Settings") | W44: =IF(H44="","",H44+ROW()/10000) | X44: =IF(OR(A44="",W44=""),"",(INT((A44-Settings!$B$6)/7)+1)*1E10+W44) | Y44: =IF(B44="","",IF(COUNTIF(B$5:B44,B44)=1,ROW(),"")) | Z44: =IF(H44="","",B44&"|"&E44) | AA44: =IF(B44="","",IF(COUNTIF(B44:B$1000,B44)=1,A44,""))
P45: =IF(F45="","",INDEX(Settings!$H$5:$H$9,1+(F45>15)+(F45>30)+(F45>45)+(F45>60))) | Q45: =IFERROR((J45+K45+L45)/H45,"") | R45: =IF(H45="","",IF(COUNTIFS(E:E,E45,P:P,P45,H:H,">=0")-1<3,"Need 3+",(SUMIFS(H:H,E:E,E45,P:P,P45)-H45)/(COUNTIFS(E:E,E45,P:P,P45,H:H,">=0")-1))) | S45: =IF(H45="","",IFERROR(ROUND(H45/R45,2),"—")) | T45: =IF(H45="","",IF(S45="—","—",IF(S45>=1.5,"🟢 Winner",IF(S45<=0.5,"🔴 Flop","Normal")))) | U45: =IF(I45="","",IF(I45>1,I45/100,I45)) | V45: =IF((COUNTIF(Settings!$D$5:$D$34,C45)+(C45=""))*(COUNTIF(Settings!$E$5:$E$34,D45)+(D45=""))*(COUNTIF(Settings!$F$5:$F$34,E45)+(E45="")),"","⚠ Not in Settings") | W45: =IF(H45="","",H45+ROW()/10000) | X45: =IF(OR(A45="",W45=""),"",(INT((A45-Settings!$B$6)/7)+1)*1E10+W45) | Y45: =IF(B45="","",IF(COUNTIF(B$5:B45,B45)=1,ROW(),"")) | Z45: =IF(H45="","",B45&"|"&E45) | AA45: =IF(B45="","",IF(COUNTIF(B45:B$1000,B45)=1,A45,""))
P46: =IF(F46="","",INDEX(Settings!$H$5:$H$9,1+(F46>15)+(F46>30)+(F46>45)+(F46>60))) | Q46: =IFERROR((J46+K46+L46)/H46,"") | R46: =IF(H46="","",IF(COUNTIFS(E:E,E46,P:P,P46,H:H,">=0")-1<3,"Need 3+",(SUMIFS(H:H,E:E,E46,P:P,P46)-H46)/(COUNTIFS(E:E,E46,P:P,P46,H:H,">=0")-1))) | S46: =IF(H46="","",IFERROR(ROUND(H46/R46,2),"—")) | T46: =IF(H46="","",IF(S46="—","—",IF(S46>=1.5,"🟢 Winner",IF(S46<=0.5,"🔴 Flop","Normal")))) | U46: =IF(I46="","",IF(I46>1,I46/100,I46)) | V46: =IF((COUNTIF(Settings!$D$5:$D$34,C46)+(C46=""))*(COUNTIF(Settings!$E$5:$E$34,D46)+(D46=""))*(COUNTIF(Settings!$F$5:$F$34,E46)+(E46="")),"","⚠ Not in Settings") | W46: =IF(H46="","",H46+ROW()/10000) | X46: =IF(OR(A46="",W46=""),"",(INT((A46-Settings!$B$6)/7)+1)*1E10+W46) | Y46: =IF(B46="","",IF(COUNTIF(B$5:B46,B46)=1,ROW(),"")) | Z46: =IF(H46="","",B46&"|"&E46) | AA46: =IF(B46="","",IF(COUNTIF(B46:B$1000,B46)=1,A46,""))
P47: =IF(F47="","",INDEX(Settings!$H$5:$H$9,1+(F47>15)+(F47>30)+(F47>45)+(F47>60))) | Q47: =IFERROR((J47+K47+L47)/H47,"") | R47: =IF(H47="","",IF(COUNTIFS(E:E,E47,P:P,P47,H:H,">=0")-1<3,"Need 3+",(SUMIFS(H:H,E:E,E47,P:P,P47)-H47)/(COUNTIFS(E:E,E47,P:P,P47,H:H,">=0")-1))) | S47: =IF(H47="","",IFERROR(ROUND(H47/R47,2),"—")) | T47: =IF(H47="","",IF(S47="—","—",IF(S47>=1.5,"🟢 Winner",IF(S47<=0.5,"🔴 Flop","Normal")))) | U47: =IF(I47="","",IF(I47>1,I47/100,I47)) | V47: =IF((COUNTIF(Settings!$D$5:$D$34,C47)+(C47=""))*(COUNTIF(Settings!$E$5:$E$34,D47)+(D47=""))*(COUNTIF(Settings!$F$5:$F$34,E47)+(E47="")),"","⚠ Not in Settings") | W47: =IF(H47="","",H47+ROW()/10000) | X47: =IF(OR(A47="",W47=""),"",(INT((A47-Settings!$B$6)/7)+1)*1E10+W47) | Y47: =IF(B47="","",IF(COUNTIF(B$5:B47,B47)=1,ROW(),"")) | Z47: =IF(H47="","",B47&"|"&E47) | AA47: =IF(B47="","",IF(COUNTIF(B47:B$1000,B47)=1,A47,""))
...

Sheet Revenue Estimator
A1: Revenue Estimator
A2: RPM differs by niche, country and platform. Use the RPM from your own analytics; the sample RPM (1.00) is a placeholder, not a benchmark.
A4: Month | B4: YT views | C4: YT RPM | D4: YT ad | E4: TT views | F4: TT RPM | G4: TT ad | H4: IG views | I4: IG RPM | J4: IG ad | K4: FB views | L4: FB RPM | M4: FB ad | N4: Affiliate (from Video Log) | O4: Sponsors / Other | P4: Monthly total
A5: =EOMONTH(Settings!$B$6,-1)+1 | B5: 25000 | C5: 1 | D5: =B5*C5/1000 | E5: 40000 | F5: 1 | G5: =E5*F5/1000 | H5: 12000 | I5: 1 | J5: =H5*I5/1000 | M5: =K5*L5/1000 | N5: =SUMIFS('Video Log'!O:O,'Video Log'!A:A,">="&A5,'Video Log'!A:A,"<"&EDATE(A5,1)) | P5: =SUM(D5,G5,J5,M5,N5,O5)
A6: =EDATE(A5,1) | B6: 30000 | C6: 1 | D6: =B6*C6/1000 | E6: 50000 | F6: 1 | G6: =E6*F6/1000 | H6: 15000 | I6: 1 | J6: =H6*I6/1000 | M6: =K6*L6/1000 | N6: =SUMIFS('Video Log'!O:O,'Video Log'!A:A,">="&A6,'Video Log'!A:A,"<"&EDATE(A6,1)) | O6: 20 | P6: =SUM(D6,G6,J6,M6,N6,O6)
A7: =EDATE(A6,1) | D7: =B7*C7/1000 | G7: =E7*F7/1000 | J7: =H7*I7/1000 | M7: =K7*L7/1000 | N7: =SUMIFS('Video Log'!O:O,'Video Log'!A:A,">="&A7,'Video Log'!A:A,"<"&EDATE(A7,1)) | P7: =SUM(D7,G7,J7,M7,N7,O7)
A8: =EDATE(A7,1) | D8: =B8*C8/1000 | G8: =E8*F8/1000 | J8: =H8*I8/1000 | M8: =K8*L8/1000 | N8: =SUMIFS('Video Log'!O:O,'Video Log'!A:A,">="&A8,'Video Log'!A:A,"<"&EDATE(A8,1)) | P8: =SUM(D8,G8,J8,M8,N8,O8)
A9: =EDATE(A8,1) | D9: =B9*C9/1000 | G9: =E9*F9/1000 | J9: =H9*I9/1000 | M9: =K9*L9/1000 | N9: =SUMIFS('Video Log'!O:O,'Video Log'!A:A,">="&A9,'Video Log'!A:A,"<"&EDATE(A9,1)) | P9: =SUM(D9,G9,J9,M9,N9,O9)
A10: =EDATE(A9,1) | D10: =B10*C10/1000 | G10: =E10*F10/1000 | J10: =H10*I10/1000 | M10: =K10*L10/1000 | N10: =SUMIFS('Video Log'!O:O,'Video Log'!A:A,">="&A10,'Video Log'!A:A,"<"&EDATE(A10,1)) | P10: =SUM(D10,G10,J10,M10,N10,O10)
A11: =EDATE(A10,1) | D11: =B11*C11/1000 | G11: =E11*F11/1000 | J11: =H11*I11/1000 | M11: =K11*L11/1000 | N11: =SUMIFS('Video Log'!O:O,'Video Log'!A:A,">="&A11,'Video Log'!A:A,"<"&EDATE(A11,1)) | P11: =SUM(D11,G11,J11,M11,N11,O11)
A12: =EDATE(A11,1) | D12: =B12*C12/1000 | G12: =E12*F12/1000 | J12: =H12*I12/1000 | M12: =K12*L12/1000 | N12: =SUMIFS('Video Log'!O:O,'Video Log'!A:A,">="&A12,'Video Log'!A:A,"<"&EDATE(A12,1)) | P12: =SUM(D12,G12,J12,M12,N12,O12)
A13: =EDATE(A12,1) | D13: =B13*C13/1000 | G13: =E13*F13/1000 | J13: =H13*I13/1000 | M13: =K13*L13/1000 | N13: =SUMIFS('Video Log'!O:O,'Video Log'!A:A,">="&A13,'Video Log'!A:A,"<"&EDATE(A13,1)) | P13: =SUM(D13,G13,J13,M13,N13,O13)
A14: =EDATE(A13,1) | D14: =B14*C14/1000 | G14: =E14*F14/1000 | J14: =H14*I14/1000 | M14: =K14*L14/1000 | N14: =SUMIFS('Video Log'!O:O,'Video Log'!A:A,">="&A14,'Video Log'!A:A,"<"&EDATE(A14,1)) | P14: =SUM(D14,G14,J14,M14,N14,O14)
A15: =EDATE(A14,1) | D15: =B15*C15/1000 | G15: =E15*F15/1000 | J15: =H15*I15/1000 | M15: =K15*L15/1000 | N15: =SUMIFS('Video Log'!O:O,'Video Log'!A:A,">="&A15,'Video Log'!A:A,"<"&EDATE(A15,1)) | P15: =SUM(D15,G15,J15,M15,N15,O15)
A16: =EDATE(A15,1) | D16: =B16*C16/1000 | G16: =E16*F16/1000 | J16: =H16*I16/1000 | M16: =K16*L16/1000 | N16: =SUMIFS('Video Log'!O:O,'Video Log'!A:A,">="&A16,'Video Log'!A:A,"<"&EDATE(A16,1)) | P16: =SUM(D16,G16,J16,M16,N16,O16)
A17: Year total | D17: =SUM(D5:D16) | G17: =SUM(G5:G16) | J17: =SUM(J5:J16) | M17: =SUM(M5:M16) | N17: =SUM(N5:N16) | O17: =SUM(O5:O16) | P17: =SUM(P5:P16)

Sheet Dashboard
A1: Dashboard
A2: All formulas. Nothing to type here. Locked with no password (Review > Unprotect Sheet).
A4: Section / item | B4: Value or posts | C4: Avg 7-day views | D4: Winners | E4: Avg % viewed | F4: Top avg | G4: Text bar | H4: Top 5 key | I4: More | J4: More | K4: More | L4: Row key
