Workbook

Sheet Start Here
A1: Start Here: Freelance Client & Invoice Tracker
A2: Read this tab once. Cream = type here · White = formula.
A4: How to use this workbook
A5: Every unpaid invoice gets its reminder email written for you. Works in Excel and Sheets.
A7: SET UP IN 4 STEPS
A8: 1. Settings: type your name, business name, currency symbol and monthly income goal.
A9: 2. Clients: add one row per client (name exactly as you will type it on invoices).
A10: 3. Projects: log leads, proposals and jobs. Invoices: log every invoice you send.
A11: 4. Every Monday: open Reminders Today, copy the subject and body, send.
A13: COLOUR LEGEND
A14: Cream cell = type here (input)
A15: White cell = formula, don't type over it
... A69: Tracking tool, not accounting, tax or legal advice.

Sheet Settings
A1: Settings
A2: Cream = type here. Stage names are fixed (dropdown); the win chance % is yours to change.
A4: Setting | B4: Value | C4: Notes / auto
A5: Your name | B5: Maya Ortiz | C5: Signs your reminder emails
A6: Business name | B6: Maya Ortiz Studio | C6: Optional
A7: Currency symbol | B7: $ | C7: Used in reminder emails only
A8: Monthly income goal | B8: 6000 | C8: Dashboard and Monthly compare to this
A9: Today | B9: =TODAY() | C9: Type a fixed date to test; put =TODAY() back
A10: Reply window days (pay-by date) | B10: 5 | C10: Pay-by date = Today + this
A11: Heads-up: due in ≤ N days | B11: 3 | C11: Reminder threshold
A12: Friendly nudge: from N days late | B12: 1 | C12: Reminder threshold
A13: Firm reminder: from N days late | B13: 8 | C13: Reminder threshold
A14: Final notice: from N days late | B14: 22 | C14: Reminder threshold
A15: Proposal follow-up after N days | B15: 5 | C15: Projects Follow-up column
A16: Late fee in my terms? | B16: No | C16: Dropdown Yes/No
A17: Late fee wording | B17: a late fee of 1.5% per month | C17: Used in Final notice when Late fee = Yes
A19: STAGE (fixed names) | C19: Win chance % is editable; Projects column O overrides it per row
A20: Lead | B20: 0.2
A21: Proposal sent | B21: 0.5
A22: Won | B22: 1
A23: In progress | B23: 1
A24: Done | B24: 1
A25: Lost | B25: 0
A27: Source dropdown: Referral, Website, Upwork, LinkedIn, Repeat client, Other
A28: Terms dropdown: 7, 14, 30, 45, 60 days
A30: REMINDER TEMPLATES | C30: Placeholders: {first} {inv} {amount} {due} {days} {paydate} {me} {latefee}
A31: Heads-up | B31: Invoice {inv} is due on {due} | C31: Subject
A32: Heads-up body | B32: Hi {first}, a quick heads-up that invoice {inv} for {amount} is due on {due}. Everything you need to pay is on the invoice. Thanks, {me} | C32: Body
A33: Friendly nudge | B33: Quick reminder: invoice {inv} | C33: Subject
A34: Friendly nudge body | B34: Hi {first}, invoice {inv} for {amount} was due on {due}, {days} days ago. Could you let me know when it's scheduled? If it's already on its way, thank you, and please ignore this. Best, {me} | C34: Body
A35: Firm reminder | B35: Invoice {inv} is now {days} days overdue | C35: Subject
A36: Firm reminder body | B36: Hi {first}, invoice {inv} for {amount} was due on {due} and is now {days} days overdue. Please pay the balance of {amount} by {paydate}, or reply with the date it will be paid. Thank you, {me} | C36: Body
A37: Final notice | B37: Final notice: invoice {inv} | C37: Subject
A38: Final notice body | B38: Hi {first}, invoice {inv} is now {days} days overdue and I haven't had a reply to my earlier reminders. If the balance of {amount} isn't paid by {paydate}, I'll pause any further work{latefee}. If there's a problem with the invoice, please reply today so we can sort it out. Regards, {me} | C38: Body ({latefee} is empty when Late fee = No)
A40: Pay-by date (auto, {paydate}) | C40: =CHOOSE(MONTH($B$9+$B$10),"Jan","Feb","Mar","Apr","May","Jun","Jul","Aug","Sep","Oct","Nov","Dec")&" "&DAY($B$9+$B$10)&", "&YEAR($B$9+$B$10)
A41: Signature (auto, {me}) | C41: =$B$5&IF($B$6="","",", "&$B$6)
A42: Late fee text (auto, {latefee}) | C42: =IF($B$16="Yes"," and add "&$B$17&" as set out in my terms","")

Sheet Clients
A1: Clients
A2: Cream = type here · White = formula. Type names exactly as you use them on Invoices and Projects.
A4: Client name | B4: Contact first name | C4: Email | D4: Source | E4: Duplicate check | F4: Invoiced | G4: Paid | H4: Outstanding | I4: Overdue | J4: Avg days to pay | K4: Flag
A5: Northwind Studio | B5: Dana | C5: dana@example.com | D5: Referral | E5: =IF(A5="","",IF(COUNTIF($A$5:$A$1000,A5)>1,"Duplicate name","")) | F5: =IF(A5="","",SUMIF(Invoices!$B$5:$B$1000,A5,Invoices!$E$5:$E$1000)) | G5: =IF(A5="","",SUMIF(Invoices!$B$5:$B$1000,A5,Invoices!$G$5:$G$1000)) | H5: =IF(A5="","",F5-G5) | I5: =IF(A5="","",SUMIFS(Invoices!$J$5:$J$1000,Invoices!$B$5:$B$1000,A5,Invoices!$K$5:$K$1000,"Overdue")) | J5: =IF(A5="","",IFERROR(AVERAGEIF(Invoices!$B$5:$B$1000,A5,Invoices!$M$5:$M$1000),"–")) | K5: =IF(A5="","",IF(COUNTIFS(Invoices!$B$5:$B$1000,A5,Invoices!$L$5:$L$1000,">="&Settings!$B$14)>0,"Ask 50% deposit",""))
A6: Harbor & Pine | B6: Leo | C6: leo@example.com | D6: Website | E6: =IF(A6="","",IF(COUNTIF($A$5:$A$1000,A6)>1,"Duplicate name","")) | F6: =IF(A6="","",SUMIF(Invoices!$B$5:$B$1000,A6,Invoices!$E$5:$E$1000)) | G6: =IF(A6="","",SUMIF(Invoices!$B$5:$B$1000,A6,Invoices!$G$5:$G$1000)) | H6: =IF(A6="","",F6-G6) | I6: =IF(A6="","",SUMIFS(Invoices!$J$5:$J$1000,Invoices!$B$5:$B$1000,A6,Invoices!$K$5:$K$1000,"Overdue")) | J6: =IF(A6="","",IFERROR(AVERAGEIF(Invoices!$B$5:$B$1000,A6,Invoices!$M$5:$M$1000),"–")) | K6: =IF(A6="","",IF(COUNTIFS(Invoices!$B$5:$B$1000,A6,Invoices!$L$5:$L$1000,">="&Settings!$B$14)>0,"Ask 50% deposit",""))
A7: Atlas Legal | B7: Marcus | C7: marcus@example.com | D7: LinkedIn | E7: =IF(A7="","",IF(COUNTIF($A$5:$A$1000,A7)>1,"Duplicate name","")) | F7: =IF(A7="","",SUMIF(Invoices!$B$5:$B$1000,A7,Invoices!$E$5:$E$1000)) | G7: =IF(A7="","",SUMIF(Invoices!$B$5:$B$1000,A7,Invoices!$G$5:$G$1000)) | H7: =IF(A7="","",F7-G7) | I7: =IF(A7="","",SUMIFS(Invoices!$J$5:$J$1000,Invoices!$B$5:$B$1000,A7,Invoices!$K$5:$K$1000,"Overdue")) | J7: =IF(A7="","",IFERROR(AVERAGEIF(Invoices!$B$5:$B$1000,A7,Invoices!$M$5:$M$1000),"–")) | K7: =IF(A7="","",IF(COUNTIFS(Invoices!$B$5:$B$1000,A7,Invoices!$L$5:$L$1000,">="&Settings!$B$14)>0,"Ask 50% deposit",""))
A8: Lumen Coffee | B8: Priya | C8: priya@example.com | D8: Referral | E8: =IF(A8="","",IF(COUNTIF($A$5:$A$1000,A8)>1,"Duplicate name","")) | F8: =IF(A8="","",SUMIF(Invoices!$B$5:$B$1000,A8,Invoices!$E$5:$E$1000)) | G8: =IF(A8="","",SUMIF(Invoices!$B$5:$B$1000,A8,Invoices!$G$5:$G$1000)) | H8: =IF(A8="","",F8-G8) | I8: =IF(A8="","",SUMIFS(Invoices!$J$5:$J$1000,Invoices!$B$5:$B$1000,A8,Invoices!$K$5:$K$1000,"Overdue")) | J8: =IF(A8="","",IFERROR(AVERAGEIF(Invoices!$B$5:$B$1000,A8,Invoices!$M$5:$M$1000),"–")) | K8: =IF(A8="","",IF(COUNTIFS(Invoices!$B$5:$B$1000,A8,Invoices!$L$5:$L$1000,">="&Settings!$B$14)>0,"Ask 50% deposit",""))
A9: Quill Health | B9: Sam | C9: sam@example.com | D9: Upwork | E9: =IF(A9="","",IF(COUNTIF($A$5:$A$1000,A9)>1,"Duplicate name","")) | F9: =IF(A9="","",SUMIF(Invoices!$B$5:$B$1000,A9,Invoices!$E$5:$E$1000)) | G9: =IF(A9="","",SUMIF(Invoices!$B$5:$B$1000,A9,Invoices!$G$5:$G$1000)) | H9: =IF(A9="","",F9-G9) | I9: =IF(A9="","",SUMIFS(Invoices!$J$5:$J$1000,Invoices!$B$5:$B$1000,A9,Invoices!$K$5:$K$1000,"Overdue")) | J9: =IF(A9="","",IFERROR(AVERAGEIF(Invoices!$B$5:$B$1000,A9,Invoices!$M$5:$M$1000),"–")) | K9: =IF(A9="","",IF(COUNTIFS(Invoices!$B$5:$B$1000,A9,Invoices!$L$5:$L$1000,">="&Settings!$B$14)>0,"Ask 50% deposit",""))
E10: =IF(A10="","",IF(COUNTIF($A$5:$A$1000,A10)>1,"Duplicate name","")) | F10: =IF(A10="","",SUMIF(Invoices!$B$5:$B$1000,A10,Invoices!$E$5:$E$1000)) | G10: =IF(A10="","",SUMIF(Invoices!$B$5:$B$1000,A10,Invoices!$G$5:$G$1000)) | H10: =IF(A10="","",F10-G10) | I10: =IF(A10="","",SUMIFS(Invoices!$J$5:$J$1000,Invoices!$B$5:$B$1000,A10,Invoices!$K$5:$K$1000,"Overdue")) | J10: =IF(A10="","",IFERROR(AVERAGEIF(Invoices!$B$5:$B$1000,A10,Invoices!$M$5:$M$1000),"–")) | K10: =IF(A10="","",IF(COUNTIFS(Invoices!$B$5:$B$1000,A10,Invoices!$L$5:$L$1000,">="&Settings!$B$14)>0,"Ask 50% deposit",""))
E11: =IF(A11="","",IF(COUNTIF($A$5:$A$1000,A11)>1,"Duplicate name","")) | F11: =IF(A11="","",SUMIF(Invoices!$B$5:$B$1000,A11,Invoices!$E$5:$E$1000)) | G11: =IF(A11="","",SUMIF(Invoices!$B$5:$B$1000,A11,Invoices!$G$5:$G$1000)) | H11: =IF(A11="","",F11-G11) | I11: =IF(A11="","",SUMIFS(Invoices!$J$5:$J$1000,Invoices!$B$5:$B$1000,A11,Invoices!$K$5:$K$1000,"Overdue")) | J11: =IF(A11="","",IFERROR(AVERAGEIF(Invoices!$B$5:$B$1000,A11,Invoices!$M$5:$M$1000),"–")) | K11: =IF(A11="","",IF(COUNTIFS(Invoices!$B$5:$B$1000,A11,Invoices!$L$5:$L$1000,">="&Settings!$B$14)>0,"Ask 50% deposit",""))
E12: =IF(A12="","",IF(COUNTIF($A$5:$A$1000,A12)>1,"Duplicate name","")) | F12: =IF(A12="","",SUMIF(Invoices!$B$5:$B$1000,A12,Invoices!$E$5:$E$1000)) | G12: =IF(A12="","",SUMIF(Invoices!$B$5:$B$1000,A12,Invoices!$G$5:$G$1000)) | H12: =IF(A12="","",F12-G12) | I12: =IF(A12="","",SUMIFS(Invoices!$J$5:$J$1000,Invoices!$B$5:$B$1000,A12,Invoices!$K$5:$K$1000,"Overdue")) | J12: =IF(A12="","",IFERROR(AVERAGEIF(Invoices!$B$5:$B$1000,A12,Invoices!$M$5:$M$1000),"–")) | K12: =IF(A12="","",IF(COUNTIFS(Invoices!$B$5:$B$1000,A12,Invoices!$L$5:$L$1000,">="&Settings!$B$14)>0,"Ask 50% deposit",""))
E13: =IF(A13="","",IF(COUNTIF($A$5:$A$1000,A13)>1,"Duplicate name","")) | F13: =IF(A13="","",SUMIF(Invoices!$B$5:$B$1000,A13,Invoices!$E$5:$E$1000)) | G13: =IF(A13="","",SUMIF(Invoices!$B$5:$B$1000,A13,Invoices!$G$5:$G$1000)) | H13: =IF(A13="","",F13-G13) | I13: =IF(A13="","",SUMIFS(Invoices!$J$5:$J$1000,Invoices!$B$5:$B$1000,A13,Invoices!$K$5:$K$1000,"Overdue")) | J13: =IF(A13="","",IFERROR(AVERAGEIF(Invoices!$B$5:$B$1000,A13,Invoices!$M$5:$M$1000),"–")) | K13: =IF(A13="","",IF(COUNTIFS(Invoices!$B$5:$B$1000,A13,Invoices!$L$5:$L$1000,">="&Settings!$B$14)>0,"Ask 50% deposit",""))
E14: =IF(A14="","",IF(COUNTIF($A$5:$A$1000,A14)>1,"Duplicate name","")) | F14: =IF(A14="","",SUMIF(Invoices!$B$5:$B$1000,A14,Invoices!$E$5:$E$1000)) | G14: =IF(A14="","",SUMIF(Invoices!$B$5:$B$1000,A14,Invoices!$G$5:$G$1000)) | H14: =IF(A14="","",F14-G14) | I14: =IF(A14="","",SUMIFS(Invoices!$J$5:$J$1000,Invoices!$B$5:$B$1000,A14,Invoices!$K$5:$K$1000,"Overdue")) | J14: =IF(A14="","",IFERROR(AVERAGEIF(Invoices!$B$5:$B$1000,A14,Invoices!$M$5:$M$1000),"–")) | K14: =IF(A14="","",IF(COUNTIFS(Invoices!$B$5:$B$1000,A14,Invoices!$L$5:$L$1000,">="&Settings!$B$14)>0,"Ask 50% deposit",""))
E15: =IF(A15="","",IF(COUNTIF($A$5:$A$1000,A15)>1,"Duplicate name","")) | F15: =IF(A15="","",SUMIF(Invoices!$B$5:$B$1000,A15,Invoices!$E$5:$E$1000)) | G15: =IF(A15="","",SUMIF(Invoices!$B$5:$B$1000,A15,Invoices!$G$5:$G$1000)) | H15: =IF(A15="","",F15-G15) | I15: =IF(A15="","",SUMIFS(Invoices!$J$5:$J$1000,Invoices!$B$5:$B$1000,A15,Invoices!$K$5:$K$1000,"Overdue")) | J15: =IF(A15="","",IFERROR(AVERAGEIF(Invoices!$B$5:$B$1000,A15,Invoices!$M$5:$M$1000),"–")) | K15: =IF(A15="","",IF(COUNTIFS(Invoices!$B$5:$B$1000,A15,Invoices!$L$5:$L$1000,">="&Settings!$B$14)>0,"Ask 50% deposit",""))
E16: =IF(A16="","",IF(COUNTIF($A$5:$A$1000,A16)>1,"Duplicate name","")) | F16: =IF(A16="","",SUMIF(Invoices!$B$5:$B$1000,A16,Invoices!$E$5:$E$1000)) | G16: =IF(A16="","",SUMIF(Invoices!$B$5:$B$1000,A16,Invoices!$G$5:$G$1000)) | H16: =IF(A16="","",F16-G16) | I16: =IF(A16="","",SUMIFS(Invoices!$J$5:$J$1000,Invoices!$B$5:$B$1000,A16,Invoices!$K$5:$K$1000,"Overdue")) | J16: =IF(A16="","",IFERROR(AVERAGEIF(Invoices!$B$5:$B$1000,A16,Invoices!$M$5:$M$1000),"–")) | K16: =IF(A16="","",IF(COUNTIFS(Invoices!$B$5:$B$1000,A16,Invoices!$L$5:$L$1000,">="&Settings!$B$14)>0,"Ask 50% deposit",""))
E17: =IF(A17="","",IF(COUNTIF($A$5:$A$1000,A17)>1,"Duplicate name","")) | F17: =IF(A17="","",SUMIF(Invoices!$B$5:$B$1000,A17,Invoices!$E$5:$E$1000)) | G17: =IF(A17="","",SUMIF(Invoices!$B$5:$B$1000,A17,Invoices!$G$5:$G$1000)) | H17: =IF(A17="","",F17-G17) | I17: =IF(A17="","",SUMIFS(Invoices!$J$5:$J$1000,Invoices!$B$5:$B$1000,A17,Invoices!$K$5:$K$1000,"Overdue")) | J17: =IF(A17="","",IFERROR(AVERAGEIF(Invoices!$B$5:$B$1000,A17,Invoices!$M$5:$M$1000),"–")) | K17: =IF(A17="","",IF(COUNTIFS(Invoices!$B$5:$B$1000,A17,Invoices!$L$5:$L$1000,">="&Settings!$B$14)>0,"Ask 50% deposit",""))
E18: =IF(A18="","",IF(COUNTIF($A$5:$A$1000,A18)>1,"Duplicate name","")) | F18: =IF(A18="","",SUMIF(Invoices!$B$5:$B$1000,A18,Invoices!$E$5:$E$1000)) | G18: =IF(A18="","",SUMIF(Invoices!$B$5:$B$1000,A18,Invoices!$G$5:$G$1000)) | H18: =IF(A18="","",F18-G18) | I18: =IF(A18="","",SUMIFS(Invoices!$J$5:$J$1000,Invoices!$B$5:$B$1000,A18,Invoices!$K$5:$K$1000,"Overdue")) | J18: =IF(A18="","",IFERROR(AVERAGEIF(Invoices!$B$5:$B$1000,A18,Invoices!$M$5:$M$1000),"–")) | K18: =IF(A18="","",IF(COUNTIFS(Invoices!$B$5:$B$1000,A18,Invoices!$L$5:$L$1000,">="&Settings!$B$14)>0,"Ask 50% deposit",""))
E19: =IF(A19="","",IF(COUNTIF($A$5:$A$1000,A19)>1,"Duplicate name","")) | F19: =IF(A19="","",SUMIF(Invoices!$B$5:$B$1000,A19,Invoices!$E$5:$E$1000)) | G19: =IF(A19="","",SUMIF(Invoices!$B$5:$B$1000,A19,Invoices!$G$5:$G$1000)) | H19: =IF(A19="","",F19-G19) | I19: =IF(A19="","",SUMIFS(Invoices!$J$5:$J$1000,Invoices!$B$5:$B$1000,A19,Invoices!$K$5:$K$1000,"Overdue")) | J19: =IF(A19="","",IFERROR(AVERAGEIF(Invoices!$B$5:$B$1000,A19,Invoices!$M$5:$M$1000),"–")) | K19: =IF(A19="","",IF(COUNTIFS(Invoices!$B$5:$B$1000,A19,Invoices!$L$5:$L$1000,">="&Settings!$B$14)>0,"Ask 50% deposit",""))
E20: =IF(A20="","",IF(COUNTIF($A$5:$A$1000,A20)>1,"Duplicate name","")) | F20: =IF(A20="","",SUMIF(Invoices!$B$5:$B$1000,A20,Invoices!$E$5:$E$1000)) | G20: =IF(A20="","",SUMIF(Invoices!$B$5:$B$1000,A20,Invoices!$G$5:$G$1000)) | H20: =IF(A20="","",F20-G20) | I20: =IF(A20="","",SUMIFS(Invoices!$J$5:$J$1000,Invoices!$B$5:$B$1000,A20,Invoices!$K$5:$K$1000,"Overdue")) | J20: =IF(A20="","",IFERROR(AVERAGEIF(Invoices!$B$5:$B$1000,A20,Invoices!$M$5:$M$1000),"–")) | K20: =IF(A20="","",IF(COUNTIFS(Invoices!$B$5:$B$1000,A20,Invoices!$L$5:$L$1000,">="&Settings!$B$14)>0,"Ask 50% deposit",""))
E21: =IF(A21="","",IF(COUNTIF($A$5:$A$1000,A21)>1,"Duplicate name","")) | F21: =IF(A21="","",SUMIF(Invoices!$B$5:$B$1000,A21,Invoices!$E$5:$E$1000)) | G21: =IF(A21="","",SUMIF(Invoices!$B$5:$B$1000,A21,Invoices!$G$5:$G$1000)) | H21: =IF(A21="","",F21-G21) | I21: =IF(A21="","",SUMIFS(Invoices!$J$5:$J$1000,Invoices!$B$5:$B$1000,A21,Invoices!$K$5:$K$1000,"Overdue")) | J21: =IF(A21="","",IFERROR(AVERAGEIF(Invoices!$B$5:$B$1000,A21,Invoices!$M$5:$M$1000),"–")) | K21: =IF(A21="","",IF(COUNTIFS(Invoices!$B$5:$B$1000,A21,Invoices!$L$5:$L$1000,">="&Settings!$B$14)>0,"Ask 50% deposit",""))
... E34: =IF(A34="","",IF(COUNTIF($A$5:$A$1000,A34)>1,"Duplicate name","")) | F34: =IF(A34="","",SUMIF(Invoices!$B$5:$B$1000,A34,Invoices!$E$5:$E$1000)) | G34: =IF(A34="","",SUMIF(Invoices!$B$5:$B$1000,A34,Invoices!$G$5:$G$1000)) | H34: =IF(A34="","",F34-G34) | I34: =IF(A34="","",SUMIFS(Invoices!$J$5:$J$1000,Invoices!$B$5:$B$1000,A34,Invoices!$K$5:$K$1000,"Overdue")) | J34: =IF(A34="","",IFERROR(AVERAGEIF(Invoices!$B$5:$B$1000,A34,Invoices!$M$5:$M$1000),"–")) | K34: =IF(A34="","",IF(COUNTIFS(Invoices!$B$5:$B$1000,A34,Invoices!$L$5:$L$1000,">="&Settings!$B$14)>0,"Ask 50% deposit",""))

Sheet Projects
A1: Projects
A2: Cream = type here · White = formula. Own win % (O) overrides the stage %; Expected close (P) feeds next month's pipeline.
A4: Project | B4: Client | C4: Stage | D4: Quoted fee | E4: Est. hours | F4: Actual hours | G4: Proposal sent | H4: Check | I4: Win chance | J4: Weighted value | K4: Planned rate | L4: Effective rate | M4: Hours over | N4: Follow-up | O4: Own win % (optional) | P4: Expected close
A5: Brand refresh | B5: Northwind Studio | C5: Done | D5: 4200 | E5: 45 | F5: 52 | H5: =IF(B5="","",IF(COUNTIF(Clients!$A$5:$A$1000,B5)=0,"Not in Clients","")) | I5: =IF(C5="","",IF(O5<>"",O5,IFERROR(VLOOKUP(C5,Settings!$A$20:$B$25,2,0),0))) | J5: =IF(OR(C5="Lead",C5="Proposal sent"),D5*I5,"") | K5: =IF(OR(D5="",E5="",E5=0),"",D5/E5) | L5: =IF(C5<>"Done","",IF(OR(F5="",F5=0),"",D5/F5)) | M5: =IF(C5<>"Done","",IF(F5="","",F5-E5)) | N5: =IF(AND(C5="Proposal sent",G5<>""),IF(Settings!$B$9-G5>=Settings!$B$15,"Follow up",""),"")
A6: Website copy + blog pack | B6: Harbor & Pine | C6: Done | D6: 3600 | E6: 36 | F6: 40 | H6: =IF(B6="","",IF(COUNTIF(Clients!$A$5:$A$1000,B6)=0,"Not in Clients","")) | I6: =IF(C6="","",IF(O6<>"",O6,IFERROR(VLOOKUP(C6,Settings!$A$20:$B$25,2,0),0))) | J6: =IF(OR(C6="Lead",C6="Proposal sent"),D6*I6,"") | K6: =IF(OR(D6="",E6="",E6=0),"",D6/E6) | L6: =IF(C6<>"Done","",IF(OR(F6="",F6=0),"",D6/F6)) | M6: =IF(C6<>"Done","",IF(F6="","",F6-E6)) | N6: =IF(AND(C6="Proposal sent",G6<>""),IF(Settings!$B$9-G6>=Settings!$B$15,"Follow up",""),"")
A7: Contract templates | B7: Atlas Legal | C7: In progress | D7: 2400 | E7: 24 | F7: 20 | H7: =IF(B7="","",IF(COUNTIF(Clients!$A$5:$A$1000,B7)=0,"Not in Clients","")) | I7: =IF(C7="","",IF(O7<>"",O7,IFERROR(VLOOKUP(C7,Settings!$A$20:$B$25,2,0),0))) | J7: =IF(OR(C7="Lead",C7="Proposal sent"),D7*I7,"") | K7: =IF(OR(D7="",E7="",E7=0),"",D7/E7) | L7: =IF(C7<>"Done","",IF(OR(F7="",F7=0),"",D7/F7)) | M7: =IF(C7<>"Done","",IF(F7="","",F7-E7)) | N7: =IF(AND(C7="Proposal sent",G7<>""),IF(Settings!$B$9-G7>=Settings!$B$15,"Follow up",""),"")
A8: Menu redesign | B8: Lumen Coffee | C8: Done | D8: 1200 | E8: 12 | F8: 18 | H8: =IF(B8="","",IF(COUNTIF(Clients!$A$5:$A$1000,B8)=0,"Not in Clients","")) | I8: =IF(C8="","",IF(O8<>"",O8,IFERROR(VLOOKUP(C8,Settings!$A$20:$B$25,2,0),0))) | J8: =IF(OR(C8="Lead",C8="Proposal sent"),D8*I8,"") | K8: =IF(OR(D8="",E8="",E8=0),"",D8/E8) | L8: =IF(C8<>"Done","",IF(OR(F8="",F8=0),"",D8/F8)) | M8: =IF(C8<>"Done","",IF(F8="","",F8-E8)) | N8: =IF(AND(C8="Proposal sent",G8<>""),IF(Settings!$B$9-G8>=Settings!$B$15,"Follow up",""),"")
A9: Onboarding emails | B9: Quill Health | C9: Won | D9: 1950 | E9: 20 | F9: 0 | H9: =IF(B9="","",IF(COUNTIF(Clients!$A$5:$A$1000,B9)=0,"Not in Clients","")) | I9: =IF(C9="","",IF(O9<>"",O9,IFERROR(VLOOKUP(C9,Settings!$A$20:$B$25,2,0),0))) | J9: =IF(OR(C9="Lead",C9="Proposal sent"),D9*I9,"") | K9: =IF(OR(D9="",E9="",E9=0),"",D9/E9) | L9: =IF(C9<>"Done","",IF(OR(F9="",F9=0),"",D9/F9)) | M9: =IF(C9<>"Done","",IF(F9="","",F9-E9)) | N9: =IF(AND(C9="Proposal sent",G9<>""),IF(Settings!$B$9-G9>=Settings!$B$15,"Follow up",""),"")
A10: Shopify build | B10: Northwind Studio | C10: Won | D10: 6500 | E10: 65 | F10: 0 | H10: =IF(B10="","",IF(COUNTIF(Clients!$A$5:$A$1000,B10)=0,"Not in Clients","")) | I10: =IF(C10="","",IF(O10<>"",O10,IFERROR(VLOOKUP(C10,Settings!$A$20:$B$25,2,0),0))) | J10: =IF(OR(C10="Lead",C10="Proposal sent"),D10*I10,"") | K10: =IF(OR(D10="",E10="",E10=0),"",D10/E10) | L10: =IF(C10<>"Done","",IF(OR(F10="",F10=0),"",D10/F10)) | M10: =IF(C10<>"Done","",IF(F10="","",F10-E10)) | N10: =IF(AND(C10="Proposal sent",G10<>""),IF(Settings!$B$9-G10>=Settings!$B$15,"Follow up",""),"")
A11: Annual report design | B11: Harbor & Pine | C11: Proposal sent | D11: 3000 | E11: 30 | G11: =Settings!$B$9-7 | H11: =IF(B11="","",IF(COUNTIF(Clients!$A$5:$A$1000,B11)=0,"Not in Clients","")) | I11: =IF(C11="","",IF(O11<>"",O11,IFERROR(VLOOKUP(C11,Settings!$A$20:$B$25,2,0),0))) | J11: =IF(OR(C11="Lead",C11="Proposal sent"),D11*I11,"") | K11: =IF(OR(D11="",E11="",E11=0),"",D11/E11) | L11: =IF(C11<>"Done","",IF(OR(F11="",F11=0),"",D11/F11)) | M11: =IF(C11<>"Done","",IF(F11="","",F11-E11)) | N11: =IF(AND(C11="Proposal sent",G11<>""),IF(Settings!$B$9-G11>=Settings!$B$15,"Follow up",""),"") | P11: =DATE(YEAR(Settings!$B$9),MONTH(Settings!$B$9)+1,15)
A12: Packaging refresh | B12: Lumen Coffee | C12: Lead | D12: 2000 | E12: 20 | H12: =IF(B12="","",IF(COUNTIF(Clients!$A$5:$A$1000,B12)=0,"Not in Clients","")) | I12: =IF(C12="","",IF(O12<>"",O12,IFERROR(VLOOKUP(C12,Settings!$A$20:$B$25,2,0),0))) | J12: =IF(OR(C12="Lead",C12="Proposal sent"),D12*I12,"") | K12: =IF(OR(D12="",E12="",E12=0),"",D12/E12) | L12: =IF(C12<>"Done","",IF(OR(F12="",F12=0),"",D12/F12)) | M12: =IF(C12<>"Done","",IF(F12="","",F12-E12)) | N12: =IF(AND(C12="Proposal sent",G12<>""),IF(Settings!$B$9-G12>=Settings!$B$15,"Follow up",""),"") | P12: =DATE(YEAR(Settings!$B$9),MONTH(Settings!$B$9)+2,1)
A13: Podcast branding | B13: Quill Health | C13: Lost | D13: 1800 | E13: 18 | H13: =IF(B13="","",IF(COUNTIF(Clients!$A$5:$A$1000,B13)=0,"Not in Clients","")) | I13: =IF(C13="","",IF(O13<>"",O13,IFERROR(VLOOKUP(C13,Settings!$A$20:$B$25,2,0),0))) | J13: =IF(OR(C13="Lead",C13="Proposal sent"),D13*I13,"") | K13: =IF(OR(D13="",E13="",E13=0),"",D13/E13) | L13: =IF(C13<>"Done","",IF(OR(F13="",F13=0),"",D13/F13)) | M13: =IF(C13<>"Done","",IF(F13="","",F13-E13)) | N13: =IF(AND(C13="Proposal sent",G13<>""),IF(Settings!$B$9-G13>=Settings!$B$15,"Follow up",""),"")
H14: =IF(B14="","",IF(COUNTIF(Clients!$A$5:$A$1000,B14)=0,"Not in Clients","")) | I14: =IF(C14="","",IF(O14<>"",O14,IFERROR(VLOOKUP(C14,Settings!$A$20:$B$25,2,0),0))) | J14: =IF(OR(C14="Lead",C14="Proposal sent"),D14*I14,"") | K14: =IF(OR(D14="",E14="",E14=0),"",D14/E14) | L14: =IF(C14<>"Done","",IF(OR(F14="",F14=0),"",D14/F14)) | M14: =IF(C14<>"Done","",IF(F14="","",F14-E14)) | N14: =IF(AND(C14="Proposal sent",G14<>""),IF(Settings!$B$9-G14>=Settings!$B$15,"Follow up",""),"")
H15: =IF(B15="","",IF(COUNTIF(Clients!$A$5:$A$1000,B15)=0,"Not in Clients","")) | I15: =IF(C15="","",IF(O15<>"",O15,IFERROR(VLOOKUP(C15,Settings!$A$20:$B$25,2,0),0))) | J15: =IF(OR(C15="Lead",C15="Proposal sent"),D15*I15,"") | K15: =IF(OR(D15="",E15="",E15=0),"",D15/E15) | L15: =IF(C15<>"Done","",IF(OR(F15="",F15=0),"",D15/F15)) | M15: =IF(C15<>"Done","",IF(F15="","",F15-E15)) | N15: =IF(AND(C15="Proposal sent",G15<>""),IF(Settings!$B$9-G15>=Settings!$B$15,"Follow up",""),"")
H16: =IF(B16="","",IF(COUNTIF(Clients!$A$5:$A$1000,B16)=0,"Not in Clients","")) | I16: =IF(C16="","",IF(O16<>"",O16,IFERROR(VLOOKUP(C16,Settings!$A$20:$B$25,2,0),0))) | J16: =IF(OR(C16="Lead",C16="Proposal sent"),D16*I16,"") | K16: =IF(OR(D16="",E16="",E16=0),"",D16/E16) | L16: =IF(C16<>"Done","",IF(OR(F16="",F16=0),"",D16/F16)) | M16: =IF(C16<>"Done","",IF(F16="","",F16-E16)) | N16: =IF(AND(C16="Proposal sent",G16<>""),IF(Settings!$B$9-G16>=Settings!$B$15,"Follow up",""),"")
H17: =IF(B17="","",IF(COUNTIF(Clients!$A$5:$A$1000,B17)=0,"Not in Clients","")) | I17: =IF(C17="","",IF(O17<>"",O17,IFERROR(VLOOKUP(C17,Settings!$A$20:$B$25,2,0),0))) | J17: =IF(OR(C17="Lead",C17="Proposal sent"),D17*I17,"") | K17: =IF(OR(D17="",E17="",E17=0),"",D17/E17) | L17: =IF(C17<>"Done","",IF(OR(F17="",F17=0),"",D17/F17)) | M17: =IF(C17<>"Done","",IF(F17="","",F17-E17)) | N17: =IF(AND(C17="Proposal sent",G17<>""),IF(Settings!$B$9-G17>=Settings!$B$15,"Follow up",""),"")
H18: =IF(B18="","",IF(COUNTIF(Clients!$A$5:$A$1000,B18)=0,"Not in Clients","")) | I18: =IF(C18="","",IF(O18<>"",O18,IFERROR(VLOOKUP(C18,Settings!$A$20:$B$25,2,0),0))) | J18: =IF(OR(C18="Lead",C18="Proposal sent"),D18*I18,"") | K18: =IF(OR(D18="",E18="",E18=0),"",D18/E18) | L18: =IF(C18<>"Done","",IF(OR(F18="",F18=0),"",D18/F18)) | M18: =IF(C18<>"Done","",IF(F18="","",F18-E18)) | N18: =IF(AND(C18="Proposal sent",G18<>""),IF(Settings!$B$9-G18>=Settings!$B$15,"Follow up",""),"")
H19: =IF(B19="","",IF(COUNTIF(Clients!$A$5:$A$1000,B19)=0,"Not in Clients","")) | I19: =IF(C19="","",IF(O19<>"",O19,IFERROR(VLOOKUP(C19,Settings!$A$20:$B$25,2,0),0))) | J19: =IF(OR(C19="Lead",C19="Proposal sent"),D19*I19,"") | K19: =IF(OR(D19="",E19="",E19=0),"",D19/E19) | L19: =IF(C19<>"Done","",IF(OR(F19="",F19=0),"",D19/F19)) | M19: =IF(C19<>"Done","",IF(F19="","",F19-E19)) | N19: =IF(AND(C19="Proposal sent",G19<>""),IF(Settings!$B$9-G19>=Settings!$B$15,"Follow up",""),"")
H20: =IF(B20="","",IF(COUNTIF(Clients!$A$5:$A$1000,B20)=0,"Not in Clients","")) | I20: =IF(C20="","",IF(O20<>"",O20,IFERROR(VLOOKUP(C20,Settings!$A$20:$B$25,2,0),0))) | J20: =IF(OR(C20="Lead",C20="Proposal sent"),D20*I20,"") | K20: =IF(OR(D20="",E20="",E20=0),"",D20/E20) | L20: =IF(C20<>"Done","",IF(OR(F20="",F20=0),"",D20/F20)) | M20: =IF(C20<>"Done","",IF(F20="","",F20-E20)) | N20: =IF(AND(C20="Proposal sent",G20<>""),IF(Settings!$B$9-G20>=Settings!$B$15,"Follow up",""),"")
H21: =IF(B21="","",IF(COUNTIF(Clients!$A$5:$A$1000,B21)=0,"Not in Clients","")) | I21: =IF(C21="","",IF(O21<>"",O21,IFERROR(VLOOKUP(C21,Settings!$A$20:$B$25,2,0),0))) | J21: =IF(OR(C21="Lead",C21="Proposal sent"),D21*I21,"") | K21: =IF(OR(D21="",E21="",E21=0),"",D21/E21) | L21: =IF(C21<>"Done","",IF(OR(F21="",F21=0),"",D21/F21)) | M21: =IF(C21<>"Done","",IF(F21="","",F21-E21)) | N21: =IF(AND(C21="Proposal sent",G21<>""),IF(Settings!$B$9-G21>=Settings!$B$15,"Follow up",""),"")
H22: =IF(B22="","",IF(COUNTIF(Clients!$A$5:$A$1000,B22)=0,"Not in Clients","")) | I22: =IF(C22="","",IF(O22<>"",O22,IFERROR(VLOOKUP(C22,Settings!$A$20:$B$25,2,0),0))) | J22: =IF(OR(C22="Lead",C22="Proposal sent"),D22*I22,"") | K22: =IF(OR(D22="",E22="",E22=0),"",D22/E22) | L22: =IF(C22<>"Done","",IF(OR(F22="",F22=0),"",D22/F22)) | M22: =IF(C22<>"Done","",IF(F22="","",F22-E22)) | N22: =IF(AND(C22="Proposal sent",G22<>""),IF(Settings!$B$9-G22>=Settings!$B$15,"Follow up",""),"")
H23: =IF(B23="","",IF(COUNTIF(Clients!$A$5:$A$1000,B23)=0,"Not in Clients","")) | I23: =IF(C23="","",IF(O23<>"",O23,IFERROR(VLOOKUP(C23,Settings!$A$20:$B$25,2,0),0))) | J23: =IF(OR(C23="Lead",C23="Proposal sent"),D23*I23,"") | K23: =IF(OR(D23="",E23="",E23=0),"",D23/E23) | L23: =IF(C23<>"Done","",IF(OR(F23="",F23=0),"",D23/F23)) | M23: =IF(C23<>"Done","",IF(F23="","",F23-E23)) | N23: =IF(AND(C23="Proposal sent",G23<>""),IF(Settings!$B$9-G23>=Settings!$B$15,"Follow up",""),"")
H24: =IF(B24="","",IF(COUNTIF(Clients!$A$5:$A$1000,B24)=0,"Not in Clients","")) | I24: =IF(C24="","",IF(O24<>"",O24,IFERROR(VLOOKUP(C24,Settings!$A$20:$B$25,2,0),0))) | J24: =IF(OR(C24="Lead",C24="Proposal sent"),D24*I24,"") | K24: =IF(OR(D24="",E24="",E24=0),"",D24/E24) | L24: =IF(C24<>"Done","",IF(OR(F24="",F24=0),"",D24/F24)) | M24: =IF(C24<>"Done","",IF(F24="","",F24-E24)) | N24: =IF(AND(C24="Proposal sent",G24<>""),IF(Settings!$B$9-G24>=Settings!$B$15,"Follow up",""),"")
H25: =IF(B25="","",IF(COUNTIF(Clients!$A$5:$A$1000,B25)=0,"Not in Clients","")) | I25: =IF(C25="","",IF(O25<>"",O25,IFERROR(VLOOKUP(C25,Settings!$A$20:$B$25,2,0),0))) | J25: =IF(OR(C25="Lead",C25="Proposal sent"),D25*I25,"") | K25: =IF(OR(D25="",E25="",E25=0),"",D25/E25) | L25: =IF(C25<>"Done","",IF(OR(F25="",F25=0),"",D25/F25)) | M25: =IF(C25<>"Done","",IF(F25="","",F25-E25)) | N25: =IF(AND(C25="Proposal sent",G25<>""),IF(Settings!$B$9-G25>=Settings!$B$15,"Follow up",""),"")
... H54: =IF(B54="","",IF(COUNTIF(Clients!$A$5:$A$1000,B54)=0,"Not in Clients","")) | I54: =IF(C54="","",IF(O54<>"",O54,IFERROR(VLOOKUP(C54,Settings!$A$20:$B$25,2,0),0))) | J54: =IF(OR(C54="Lead",C54="Proposal sent"),D54*I54,"") | K54: =IF(OR(D54="",E54="",E54=0),"",D54/E54) | L54: =IF(C54<>"Done","",IF(OR(F54="",F54=0),"",D54/F54)) | M54: =IF(C54<>"Done","",IF(F54="","",F54-E54)) | N54: =IF(AND(C54="Proposal sent",G54<>""),IF(Settings!$B$9-G54>=Settings!$B$15,"Follow up",""),"")

Sheet Invoices
A1: Invoices
A2: Cream = type here · White = formula. Sample dates are formulas relative to Settings Today: type over them.
A4: Invoice # | B4: Client | C4: Issue date | D4: Terms days | E4: Amount | F4: Paid date | G4: Amount paid | H4: Check | I4: Due date | J4: Balance | K4: Status | L4: Days overdue | M4: Days to pay | N4: Send this | O4: Reminder score (helper)
A5: INV-001 | B5: Northwind Studio | C5: =Settings!$B$9-40 | D5: 14 | E5: 4200 | F5: =Settings!$B$9-31 | G5: 4200 | H5: =IF(B5="","",IF(COUNTIF(Clients!$A$5:$A$1000,B5)=0,"Not in Clients","")) | I5: =IF(OR(C5="",D5=""),"",C5+D5) | J5: =IF(A5="","",E5-G5) | K5: =IF(A5="","",IF(J5<=0,"Paid",IF(I5="","Open",IF(Settings!$B$9>I5,"Overdue",IF(I5-Settings!$B$9<=Settings!$B$11,"Due soon","Open"))))) | L5: =IF(K5="Overdue",Settings!$B$9-I5,IF(A5="","",0)) | M5: =IF(A5="","",IF(AND(J5<=0,F5<>""),F5-C5,"")) | N5: =IF(K5="Overdue",IF(L5>=Settings!$B$14,"Final notice",IF(L5>=Settings!$B$13,"Firm reminder",IF(L5>=Settings!$B$12,"Friendly nudge",""))),IF(K5="Due soon","Heads-up","")) | O5: =IF(N5="",0,L5+1-ROW()/100000)
A6: INV-002 | B6: Harbor & Pine | C6: =Settings!$B$9-35 | D6: 30 | E6: 2700 | F6: =Settings!$B$9-12 | G6: 2700 | H6: =IF(B6="","",IF(COUNTIF(Clients!$A$5:$A$1000,B6)=0,"Not in Clients","")) | I6: =IF(OR(C6="",D6=""),"",C6+D6) | J6: =IF(A6="","",E6-G6) | K6: =IF(A6="","",IF(J6<=0,"Paid",IF(I6="","Open",IF(Settings!$B$9>I6,"Overdue",IF(I6-Settings!$B$9<=Settings!$B$11,"Due soon","Open"))))) | L6: =IF(K6="Overdue",Settings!$B$9-I6,IF(A6="","",0)) | M6: =IF(A6="","",IF(AND(J6<=0,F6<>""),F6-C6,"")) | N6: =IF(K6="Overdue",IF(L6>=Settings!$B$14,"Final notice",IF(L6>=Settings!$B$13,"Firm reminder",IF(L6>=Settings!$B$12,"Friendly nudge",""))),IF(K6="Due soon","Heads-up","")) | O6: =IF(N6="",0,L6+1-ROW()/100000)
A7: INV-003 | B7: Atlas Legal | C7: =Settings!$B$9-40 | D7: 14 | E7: 1200 | G7: 0 | H7: =IF(B7="","",IF(COUNTIF(Clients!$A$5:$A$1000,B7)=0,"Not in Clients","")) | I7: =IF(OR(C7="",D7=""),"",C7+D7) | J7: =IF(A7="","",E7-G7) | K7: =IF(A7="","",IF(J7<=0,"Paid",IF(I7="","Open",IF(Settings!$B$9>I7,"Overdue",IF(I7-Settings!$B$9<=Settings!$B$11,"Due soon","Open"))))) | L7: =IF(K7="Overdue",Settings!$B$9-I7,IF(A7="","",0)) | M7: =IF(A7="","",IF(AND(J7<=0,F7<>""),F7-C7,"")) | N7: =IF(K7="Overdue",IF(L7>=Settings!$B$14,"Final notice",IF(L7>=Settings!$B$13,"Firm reminder",IF(L7>=Settings!$B$12,"Friendly nudge",""))),IF(K7="Due soon","Heads-up","")) | O7: =IF(N7="",0,L7+1-ROW()/100000)
A8: INV-004 | B8: Lumen Coffee | C8: =Settings!$B$9-21 | D8: 7 | E8: 1200 | F8: =Settings!$B$9-10 | G8: 600 | H8: =IF(B8="","",IF(COUNTIF(Clients!$A$5:$A$1000,B8)=0,"Not in Clients","")) | I8: =IF(OR(C8="",D8=""),"",C8+D8) | J8: =IF(A8="","",E8-G8) | K8: =IF(A8="","",IF(J8<=0,"Paid",IF(I8="","Open",IF(Settings!$B$9>I8,"Overdue",IF(I8-Settings!$B$9<=Settings!$B$11,"Due soon","Open"))))) | L8: =IF(K8="Overdue",Settings!$B$9-I8,IF(A8="","",0)) | M8: =IF(A8="","",IF(AND(J8<=0,F8<>""),F8-C8,"")) | N8: =IF(K8="Overdue",IF(L8>=Settings!$B$14,"Final notice",IF(L8>=Settings!$B$13,"Firm reminder",IF(L8>=Settings!$B$12,"Friendly nudge",""))),IF(K8="Due soon","Heads-up","")) | O8: =IF(N8="",0,L8+1-ROW()/100000)
A9: INV-005 | B9: Atlas Legal | C9: =Settings!$B$9-18 | D9: 14 | E9: 1200 | G9: 0 | H9: =IF(B9="","",IF(COUNTIF(Clients!$A$5:$A$1000,B9)=0,"Not in Clients","")) | I9: =IF(OR(C9="",D9=""),"",C9+D9) | J9: =IF(A9="","",E9-G9) | K9: =IF(A9="","",IF(J9<=0,"Paid",IF(I9="","Open",IF(Settings!$B$9>I9,"Overdue",IF(I9-Settings!$B$9<=Settings!$B$11,"Due soon","Open"))))) | L9: =IF(K9="Overdue",Settings!$B$9-I9,IF(A9="","",0)) | M9: =IF(A9="","",IF(AND(J9<=0,F9<>""),F9-C9,"")) | N9: =IF(K9="Overdue",IF(L9>=Settings!$B$14,"Final notice",IF(L9>=Settings!$B$13,"Firm reminder",IF(L9>=Settings!$B$12,"Friendly nudge",""))),IF(K9="Due soon","Heads-up","")) | O9: =IF(N9="",0,L9+1-ROW()/100000)
A10: INV-006 | B10: Quill Health | C10: =Settings!$B$9-12 | D10: 14 | E10: 1950 | G10: 0 | H10: =IF(B10="","",IF(COUNTIF(Clients!$A$5:$A$1000,B10)=0,"Not in Clients","")) | I10: =IF(OR(C10="",D10=""),"",C10+D10) | J10: =IF(A10="","",E10-G10) | K10: =IF(A10="","",IF(J10<=0,"Paid",IF(I10="","Open",IF(Settings!$B$9>I10,"Overdue",IF(I10-Settings!$B$9<=Settings!$B$11,"Due soon","Open"))))) | L10: =IF(K10="Overdue",Settings!$B$9-I10,IF(A10="","",0)) | M10: =IF(A10="","",IF(AND(J10<=0,F10<>""),F10-C10,"")) | N10: =IF(K10="Overdue",IF(L10>=Settings!$B$14,"Final notice",IF(L10>=Settings!$B$13,"Firm reminder",IF(L10>=Settings!$B$12,"Friendly nudge",""))),IF(K10="Due soon","Heads-up","")) | O10: =IF(N10="",0,L10+1-ROW()/100000)
A11: INV-007 | B11: Northwind Studio | C11: =Settings!$B$9-5 | D11: 30 | E11: 3250 | G11: 0 | H11: =IF(B11="","",IF(COUNTIF(Clients!$A$5:$A$1000,B11)=0,"Not in Clients","")) | I11: =IF(OR(C11="",D11=""),"",C11+D11) | J11: =IF(A11="","",E11-G11) | K11: =IF(A11="","",IF(J11<=0,"Paid",IF(I11="","Open",IF(Settings!$B$9>I11,"Overdue",IF(I11-Settings!$B$9<=Settings!$B$11,"Due soon","Open"))))) | L11: =IF(K11="Overdue",Settings!$B$9-I11,IF(A11="","",0)) | M11: =IF(A11="","",IF(AND(J11<=0,F11<>""),F11-C11,"")) | N11: =IF(K11="Overdue",IF(L11>=Settings!$B$14,"Final notice",IF(L11>=Settings!$B$13,"Firm reminder",IF(L11>=Settings!$B$12,"Friendly nudge",""))),IF(K11="Due soon","Heads-up","")) | O11: =IF(N11="",0,L11+1-ROW()/100000)
A12: INV-008 | B12: Harbor & Pine | C12: =Settings!$B$9-3 | D12: 14 | E12: 900 | F12: =Settings!$B$9-1 | G12: 900 | H12: =IF(B12="","",IF(COUNTIF(Clients!$A$5:$A$1000,B12)=0,"Not in Clients","")) | I12: =IF(OR(C12="",D12=""),"",C12+D12) | J12: =IF(A12="","",E12-G12) | K12: =IF(A12="","",IF(J12<=0,"Paid",IF(I12="","Open",IF(Settings!$B$9>I12,"Overdue",IF(I12-Settings!$B$9<=Settings!$B$11,"Due soon","Open"))))) | L12: =IF(K12="Overdue",Settings!$B$9-I12,IF(A12="","",0)) | M12: =IF(A12="","",IF(AND(J12<=0,F12<>""),F12-C12,"")) | N12: =IF(K12="Overdue",IF(L12>=Settings!$B$14,"Final notice",IF(L12>=Settings!$B$13,"Firm reminder",IF(L12>=Settings!$B$12,"Friendly nudge",""))),IF(K12="Due soon","Heads-up","")) | O12: =IF(N12="",0,L12+1-ROW()/100000)
H13: =IF(B13="","",IF(COUNTIF(Clients!$A$5:$A$1000,B13)=0,"Not in Clients","")) | I13: =IF(OR(C13="",D13=""),"",C13+D13) | J13: =IF(A13="","",E13-G13) | K13: =IF(A13="","",IF(J13<=0,"Paid",IF(I13="","Open",IF(Settings!$B$9>I13,"Overdue",IF(I13-Settings!$B$9<=Settings!$B$11,"Due soon","Open"))))) | L13: =IF(K13="Overdue",Settings!$B$9-I13,IF(A13="","",0)) | M13: =IF(A13="","",IF(AND(J13<=0,F13<>""),F13-C13,"")) | N13: =IF(K13="Overdue",IF(L13>=Settings!$B$14,"Final notice",IF(L13>=Settings!$B$13,"Firm reminder",IF(L13>=Settings!$B$12,"Friendly nudge",""))),IF(K13="Due soon","Heads-up","")) | O13: =IF(N13="",0,L13+1-ROW()/100000)
H14: =IF(B14="","",IF(COUNTIF(Clients!$A$5:$A$1000,B14)=0,"Not in Clients","")) | I14: =IF(OR(C14="",D14=""),"",C14+D14) | J14: =IF(A14="","",E14-G14) | K14: =IF(A14="","",IF(J14<=0,"Paid",IF(I14="","Open",IF(Settings!$B$9>I14,"Overdue",IF(I14-Settings!$B$9<=Settings!$B$11,"Due soon","Open"))))) | L14: =IF(K14="Overdue",Settings!$B$9-I14,IF(A14="","",0)) | M14: =IF(A14="","",IF(AND(J14<=0,F14<>""),F14-C14,"")) | N14: =IF(K14="Overdue",IF(L14>=Settings!$B$14,"Final notice",IF(L14>=Settings!$B$13,"Firm reminder",IF(L14>=Settings!$B$12,"Friendly nudge",""))),IF(K14="Due soon","Heads-up","")) | O14: =IF(N14="",0,L14+1-ROW()/100000)
H15: =IF(B15="","",IF(COUNTIF(Clients!$A$5:$A$1000,B15)=0,"Not in Clients","")) | I15: =IF(OR(C15="",D15=""),"",C15+D15) | J15: =IF(A15="","",E15-G15) | K15: =IF(A15="","",IF(J15<=0,"Paid",IF(I15="","Open",IF(Settings!$B$9>I15,"Overdue",IF(I15-Settings!$B$9<=Settings!$B$11,"Due soon","Open"))))) | L15: =IF(K15="Overdue",Settings!$B$9-I15,IF(A15="","",0)) | M15: =IF(A15="","",IF(AND(J15<=0,F15<>""),F15-C15,"")) | N15: =IF(K15="Overdue",IF(L15>=Settings!$B$14,"Final notice",IF(L15>=Settings!$B$13,"Firm reminder",IF(L15>=Settings!$B$12,"Friendly nudge",""))),IF(K15="Due soon","Heads-up","")) | O15: =IF(N15="",0,L15+1-ROW()/100000)
H16: =IF(B16="","",IF(COUNTIF(Clients!$A$5:$A$1000,B16)=0,"Not in Clients","")) | I16: =IF(OR(C16="",D16=""),"",C16+D16) | J16: =IF(A16="","",E16-G16) | K16: =IF(A16="","",IF(J16<=0,"Paid",IF(I16="","Open",IF(Settings!$B$9>I16,"Overdue",IF(I16-Settings!$B$9<=Settings!$B$11,"Due soon","Open"))))) | L16: =IF(K16="Overdue",Settings!$B$9-I16,IF(A16="","",0)) | M16: =IF(A16="","",IF(AND(J16<=0,F16<>""),F16-C16,"")) | N16: =IF(K16="Overdue",IF(L16>=Settings!$B$14,"Final notice",IF(L16>=Settings!$B$13,"Firm reminder",IF(L16>=Settings!$B$12,"Friendly nudge",""))),IF(K16="Due soon","Heads-up","")) | O16: =IF(N16="",0,L16+1-ROW()/100000)
H17: =IF(B17="","",IF(COUNTIF(Clients!$A$5:$A$1000,B17)=0,"Not in Clients","")) | I17: =IF(OR(C17="",D17=""),"",C17+D17) | J17: =IF(A17="","",E17-G17) | K17: =IF(A17="","",IF(J17<=0,"Paid",IF(I17="","Open",IF(Settings!$B$9>I17,"Overdue",IF(I17-Settings!$B$9<=Settings!$B$11,"Due soon","Open"))))) | L17: =IF(K17="Overdue",Settings!$B$9-I17,IF(A17="","",0)) | M17: =IF(A17="","",IF(AND(J17<=0,F17<>""),F17-C17,"")) | N17: =IF(K17="Overdue",IF(L17>=Settings!$B$14,"Final notice",IF(L17>=Settings!$B$13,"Firm reminder",IF(L17>=Settings!$B$12,"Friendly nudge",""))),IF(K17="Due soon","Heads-up","")) | O17: =IF(N17="",0,L17+1-ROW()/100000)
H18: =IF(B18="","",IF(COUNTIF(Clients!$A$5:$A$1000,B18)=0,"Not in Clients","")) | I18: =IF(OR(C18="",D18=""),"",C18+D18) | J18: =IF(A18="","",E18-G18) | K18: =IF(A18="","",IF(J18<=0,"Paid",IF(I18="","Open",IF(Settings!$B$9>I18,"Overdue",IF(I18-Settings!$B$9<=Settings!$B$11,"Due soon","Open"))))) | L18: =IF(K18="Overdue",Settings!$B$9-I18,IF(A18="","",0)) | M18: =IF(A18="","",IF(AND(J18<=0,F18<>""),F18-C18,"")) | N18: =IF(K18="Overdue",IF(L18>=Settings!$B$14,"Final notice",IF(L18>=Settings!$B$13,"Firm reminder",IF(L18>=Settings!$B$12,"Friendly nudge",""))),IF(K18="Due soon","Heads-up","")) | O18: =IF(N18="",0,L18+1-ROW()/100000)
H19: =IF(B19="","",IF(COUNTIF(Clients!$A$5:$A$1000,B19)=0,"Not in Clients","")) | I19: =IF(OR(C19="",D19=""),"",C19+D19) | J19: =IF(A19="","",E19-G19) | K19: =IF(A19="","",IF(J19<=0,"Paid",IF(I19="","Open",IF(Settings!$B$9>I19,"Overdue",IF(I19-Settings!$B$9<=Settings!$B$11,"Due soon","Open"))))) | L19: =IF(K19="Overdue",Settings!$B$9-I19,IF(A19="","",0)) | M19: =IF(A19="","",IF(AND(J19<=0,F19<>""),F19-C19,"")) | N19: =IF(K19="Overdue",IF(L19>=Settings!$B$14,"Final notice",IF(L19>=Settings!$B$13,"Firm reminder",IF(L19>=Settings!$B$12,"Friendly nudge",""))),IF(K19="Due soon","Heads-up","")) | O19: =IF(N19="",0,L19+1-ROW()/100000)
H20: =IF(B20="","",IF(COUNTIF(Clients!$A$5:$A$1000,B20)=0,"Not in Clients","")) | I20: =IF(OR(C20="",D20=""),"",C20+D20) | J20: =IF(A20="","",E20-G20) | K20: =IF(A20="","",IF(J20<=0,"Paid",IF(I20="","Open",IF(Settings!$B$9>I20,"Overdue",IF(I20-Settings!$B$9<=Settings!$B$11,"Due soon","Open"))))) | L20: =IF(K20="Overdue",Settings!$B$9-I20,IF(A20="","",0)) | M20: =IF(A20="","",IF(AND(J20<=0,F20<>""),F20-C20,"")) | N20: =IF(K20="Overdue",IF(L20>=Settings!$B$14,"Final notice",IF(L20>=Settings!$B$13,"Firm reminder",IF(L20>=Settings!$B$12,"Friendly nudge",""))),IF(K20="Due soon","Heads-up","")) | O20: =IF(N20="",0,L20+1-ROW()/100000)
H21: =IF(B21="","",IF(COUNTIF(Clients!$A$5:$A$1000,B21)=0,"Not in Clients","")) | I21: =IF(OR(C21="",D21=""),"",C21+D21) | J21: =IF(A21="","",E21-G21) | K21: =IF(A21="","",IF(J21<=0,"Paid",IF(I21="","Open",IF(Settings!$B$9>I21,"Overdue",IF(I21-Settings!$B$9<=Settings!$B$11,"Due soon","Open"))))) | L21: =IF(K21="Overdue",Settings!$B$9-I21,IF(A21="","",0)) | M21: =IF(A21="","",IF(AND(J21<=0,F21<>""),F21-C21,"")) | N21: =IF(K21="Overdue",IF(L21>=Settings!$B$14,"Final notice",IF(L21>=Settings!$B$13,"Firm reminder",IF(L21>=Settings!$B$12,"Friendly nudge",""))),IF(K21="Due soon","Heads-up","")) | O21: =IF(N21="",0,L21+1-ROW()/100000)
H22: =IF(B22="","",IF(COUNTIF(Clients!$A$5:$A$1000,B22)=0,"Not in Clients","")) | I22: =IF(OR(C22="",D22=""),"",C22+D22) | J22: =IF(A22="","",E22-G22) | K22: =IF(A22="","",IF(J22<=0,"Paid",IF(I22="","Open",IF(Settings!$B$9>I22,"Overdue",IF(I22-Settings!$B$9<=Settings!$B$11,"Due soon","Open"))))) | L22: =IF(K22="Overdue",Settings!$B$9-I22,IF(A22="","",0)) | M22: =IF(A22="","",IF(AND(J22<=0,F22<>""),F22-C22,"")) | N22: =IF(K22="Overdue",IF(L22>=Settings!$B$14,"Final notice",IF(L22>=Settings!$B$13,"Firm reminder",IF(L22>=Settings!$B$12,"Friendly nudge",""))),IF(K22="Due soon","Heads-up","")) | O22: =IF(N22="",0,L22+1-ROW()/100000)
H23: =IF(B23="","",IF(COUNTIF(Clients!$A$5:$A$1000,B23)=0,"Not in Clients","")) | I23: =IF(OR(C23="",D23=""),"",C23+D23) | J23: =IF(A23="","",E23-G23) | K23: =IF(A23="","",IF(J23<=0,"Paid",IF(I23="","Open",IF(Settings!$B$9>I23,"Overdue",IF(I23-Settings!$B$9<=Settings!$B$11,"Due soon","Open"))))) | L23: =IF(K23="Overdue",Settings!$B$9-I23,IF(A23="","",0)) | M23: =IF(A23="","",IF(AND(J23<=0,F23<>""),F23-C23,"")) | N23: =IF(K23="Overdue",IF(L23>=Settings!$B$14,"Final notice",IF(L23>=Settings!$B$13,"Firm reminder",IF(L23>=Settings!$B$12,"Friendly nudge",""))),IF(K23="Due soon","Heads-up","")) | O23: =IF(N23="",0,L23+1-ROW()/100000)
H24: =IF(B24="","",IF(COUNTIF(Clients!$A$5:$A$1000,B24)=0,"Not in Clients","")) | I24: =IF(OR(C24="",D24=""),"",C24+D24) | J24: =IF(A24="","",E24-G24) | K24: =IF(A24="","",IF(J24<=0,"Paid",IF(I24="","Open",IF(Settings!$B$9>I24,"Overdue",IF(I24-Settings!$B$9<=Settings!$B$11,"Due soon","Open"))))) | L24: =IF(K24="Overdue",Settings!$B$9-I24,IF(A24="","",0)) | M24: =IF(A24="","",IF(AND(J24<=0,F24<>""),F24-C24,"")) | N24: =IF(K24="Overdue",IF(L24>=Settings!$B$14,"Final notice",IF(L24>=Settings!$B$13,"Firm reminder",IF(L24>=Settings!$B$12,"Friendly nudge",""))),IF(K24="Due soon","Heads-up","")) | O24: =IF(N24="",0,L24+1-ROW()/100000)
... H64: =IF(B64="","",IF(COUNTIF(Clients!$A$5:$A$1000,B64)=0,"Not in Clients","")) | I64: =IF(OR(C64="",D64=""),"",C64+D64) | J64: =IF(A64="","",E64-G64) | K64: =IF(A64="","",IF(J64<=0,"Paid",IF(I64="","Open",IF(Settings!$B$9>I64,"Overdue",IF(I64-Settings!$B$9<=Settings!$B$11,"Due soon","Open"))))) | L64: =IF(K64="Overdue",Settings!$B$9-I64,IF(A64="","",0)) | M64: =IF(A64="","",IF(AND(J64<=0,F64<>""),F64-C64,"")) | N64: =IF(K64="Overdue",IF(L64>=Settings!$B$14,"Final notice",IF(L64>=Settings!$B$13,"Firm reminder",IF(L64>=Settings!$B$12,"Friendly nudge",""))),IF(K64="Due soon","Heads-up","")) | O64: =IF(N64="",0,L64+1-ROW()/100000)

Sheet Monthly
A1: Monthly
A2: Invoiced by issue date, collected by paid date, pipeline by expected close. Not locked: select A4:C16 → Insert → Chart.
A4: Month | B4: Invoiced | C4: Collected | D4: Collected vs goal | E4: Bar (20 blocks = 100%) | F4: Pipeline expected (weighted) | H4: Year
A5: Jan | B5: =SUMIFS(Invoices!$E$5:$E$1000,Invoices!$C$5:$C$1000,">="&DATE($H$5,1,1),Invoices!$C$5:$C$1000,"<"&DATE($H$5,2,1)) | C5: =SUMIFS(Invoices!$G$5:$G$1000,Invoices!$F$5:$F$1000,">="&DATE($H$5,1,1),Invoices!$F$5:$F$1000,"<"&DATE($H$5,2,1)) | D5: =IF(Settings!$B$8>0,C5/Settings!$B$8,"") | E5: =IF(D5="","",REPT("█",ROUND(MIN(D5,1)*20,0))&REPT("░",20-ROUND(MIN(D5,1)*20,0))) | F5: =SUMIFS(Projects!$J$5:$J$1000,Projects!$P$5:$P$1000,">="&DATE($H$5,1,1),Projects!$P$5:$P$1000,"<"&DATE($H$5,2,1)) | H5: =YEAR(Settings!$B$9)
A6: Feb | B6: =SUMIFS(Invoices!$E$5:$E$1000,Invoices!$C$5:$C$1000,">="&DATE($H$5,2,1),Invoices!$C$5:$C$1000,"<"&DATE($H$5,3,1)) | C6: =SUMIFS(Invoices!$G$5:$G$1000,Invoices!$F$5:$F$1000,">="&DATE($H$5,2,1),Invoices!$F$5:$F$1000,"<"&DATE($H$5,3,1)) | D6: =IF(Settings!$B$8>0,C6/Settings!$B$8,"") | E6: =IF(D6="","",REPT("█",ROUND(MIN(D6,1)*20,0))&REPT("░",20-ROUND(MIN(D6,1)*20,0))) | F6: =SUMIFS(Projects!$J$5:$J$1000,Projects!$P$5:$P$1000,">="&DATE($H$5,2,1),Projects!$P$5:$P$1000,"<"&DATE($H$5,3,1))
A7: Mar | B7: =SUMIFS(Invoices!$E$5:$E$1000,Invoices!$C$5:$C$1000,">="&DATE($H$5,3,1),Invoices!$C$5:$C$1000,"<"&DATE($H$5,4,1)) | C7: =SUMIFS(Invoices!$G$5:$G$1000,Invoices!$F$5:$F$1000,">="&DATE($H$5,3,1),Invoices!$F$5:$F$1000,"<"&DATE($H$5,4,1)) | D7: =IF(Settings!$B$8>0,C7/Settings!$B$8,"") | E7: =IF(D7="","",REPT("█",ROUND(MIN(D7,1)*20,0))&REPT("░",20-ROUND(MIN(D7,1)*20,0))) | F7: =SUMIFS(Projects!$J$5:$J$1000,Projects!$P$5:$P$1000,">="&DATE($H$5,3,1),Projects!$P$5:$P$1000,"<"&DATE($H$5,4,1))
A8: Apr | B8: =SUMIFS(Invoices!$E$5:$E$1000,Invoices!$C$5:$C$1000,">="&DATE($H$5,4,1),Invoices!$C$5:$C$1000,"<"&DATE($H$5,5,1)) | C8: =SUMIFS(Invoices!$G$5:$G$1000,Invoices!$F$5:$F$1000,">="&DATE($H$5,4,1),Invoices!$F$5:$F$1000,"<"&DATE($H$5,5,1)) | D8: =IF(Settings!$B$8>0,C8/Settings!$B$8,"") | E8: =IF(D8="","",REPT("█",ROUND(MIN(D8,1)*20,0))&REPT("░",20-ROUND(MIN(D8,1)*20,0))) | F8: =SUMIFS(Projects!$J$5:$J$1000,Projects!$P$5:$P$1000,">="&DATE($H$5,4,1),Projects!$P$5:$P$1000,"<"&DATE($H$5,5,1))
A9: May | B9: =SUMIFS(Invoices!$E$5:$E$1000,Invoices!$C$5:$C$1000,">="&DATE($H$5,5,1),Invoices!$C$5:$C$1000,"<"&DATE($H$5,6,1)) | C9: =SUMIFS(Invoices!$G$5:$G$1000,Invoices!$F$5:$F$1000,">="&DATE($H$5,5,1),Invoices!$F$5:$F$1000,"<"&DATE($H$5,6,1)) | D9: =IF(Settings!$B$8>0,C9/Settings!$B$8,"") | E9: =IF(D9="","",REPT("█",ROUND(MIN(D9,1)*20,0))&REPT("░",20-ROUND(MIN(D9,1)*20,0))) | F9: =SUMIFS(Projects!$J$5:$J$1000,Projects!$P$5:$P$1000,">="&DATE($H$5,5,1),Projects!$P$5:$P$1000,"<"&DATE($H$5,6,1))
A10: Jun | B10: =SUMIFS(Invoices!$E$5:$E$1000,Invoices!$C$5:$C$1000,">="&DATE($H$5,6,1),Invoices!$C$5:$C$1000,"<"&DATE($H$5,7,1)) | C10: =SUMIFS(Invoices!$G$5:$G$1000,Invoices!$F$5:$F$1000,">="&DATE($H$5,6,1),Invoices!$F$5:$F$1000,"<"&DATE($H$5,7,1)) | D10: =IF(Settings!$B$8>0,C10/Settings!$B$8,"") | E10: =IF(D10="","",REPT("█",ROUND(MIN(D10,1)*20,0))&REPT("░",20-ROUND(MIN(D10,1)*20,0))) | F10: =SUMIFS(Projects!$J$5:$J$1000,Projects!$P$5:$P$1000,">="&DATE($H$5,6,1),Projects!$P$5:$P$1000,"<"&DATE($H$5,7,1))
A11: Jul | B11: =SUMIFS(Invoices!$E$5:$E$1000,Invoices!$C$5:$C$1000,">="&DATE($H$5,7,1),Invoices!$C$5:$C$1000,"<"&DATE($H$5,8,1)) | C11: =SUMIFS(Invoices!$G$5:$G$1000,Invoices!$F$5:$F$1000,">="&DATE($H$5,7,1),Invoices!$F$5:$F$1000,"<"&DATE($H$5,8,1)) | D11: =IF(Settings!$B$8>0,C11/Settings!$B$8,"") | E11: =IF(D11="","",REPT("█",ROUND(MIN(D11,1)*20,0))&REPT("░",20-ROUND(MIN(D11,1)*20,0))) | F11: =SUMIFS(Projects!$J$5:$J$1000,Projects!$P$5:$P$1000,">="&DATE($H$5,7,1),Projects!$P$5:$P$1000,"<"&DATE($H$5,8,1))
A12: Aug | B12: =SUMIFS(Invoices!$E$5:$E$1000,Invoices!$C$5:$C$1000,">="&DATE($H$5,8,1),Invoices!$C$5:$C$1000,"<"&DATE($H$5,9,1)) | C12: =SUMIFS(Invoices!$G$5:$G$1000,Invoices!$F$5:$F$1000,">="&DATE($H$5,8,1),Invoices!$F$5:$F$1000,"<"&DATE($H$5,9,1)) | D12: =IF(Settings!$B$8>0,C12/Settings!$B$8,"") | E12: =IF(D12="","",REPT("█",ROUND(MIN(D12,1)*20,0))&REPT("░",20-ROUND(MIN(D12,1)*20,0))) | F12: =SUMIFS(Projects!$J$5:$J$1000,Projects!$P$5:$P$1000,">="&DATE($H$5,8,1),Projects!$P$5:$P$1000,"<"&DATE($H$5,9,1))
A13: Sep | B13: =SUMIFS(Invoices!$E$5:$E$1000,Invoices!$C$5:$C$1000,">="&DATE($H$5,9,1),Invoices!$C$5:$C$1000,"<"&DATE($H$5,10,1)) | C13: =SUMIFS(Invoices!$G$5:$G$1000,Invoices!$F$5:$F$1000,">="&DATE($H$5,9,1),Invoices!$F$5:$F$1000,"<"&DATE($H$5,10,1)) | D13: =IF(Settings!$B$8>0,C13/Settings!$B$8,"") | E13: =IF(D13="","",REPT("█",ROUND(MIN(D13,1)*20,0))&REPT("░",20-ROUND(MIN(D13,1)*20,0))) | F13: =SUMIFS(Projects!$J$5:$J$1000,Projects!$P$5:$P$1000,">="&DATE($H$5,9,1),Projects!$P$5:$P$1000,"<"&DATE($H$5,10,1))
A14: Oct | B14: =SUMIFS(Invoices!$E$5:$E$1000,Invoices!$C$5:$C$1000,">="&DATE($H$5,10,1),Invoices!$C$5:$C$1000,"<"&DATE($H$5,11,1)) | C14: =SUMIFS(Invoices!$G$5:$G$1000,Invoices!$F$5:$F$1000,">="&DATE($H$5,10,1),Invoices!$F$5:$F$1000,"<"&DATE($H$5,11,1)) | D14: =IF(Settings!$B$8>0,C14/Settings!$B$8,"") | E14: =IF(D14="","",REPT("█",ROUND(MIN(D14,1)*20,0))&REPT("░",20-ROUND(MIN(D14,1)*20,0))) | F14: =SUMIFS(Projects!$J$5:$J$1000,Projects!$P$5:$P$1000,">="&DATE($H$5,10,1),Projects!$P$5:$P$1000,"<"&DATE($H$5,11,1))
A15: Nov | B15: =SUMIFS(Invoices!$E$5:$E$1000,Invoices!$C$5:$C$1000,">="&DATE($H$5,11,1),Invoices!$C$5:$C$1000,"<"&DATE($H$5,12,1)) | C15: =SUMIFS(Invoices!$G$5:$G$1000,Invoices!$F$5:$F$1000,">="&DATE($H$5,11,1),Invoices!$F$5:$F$1000,"<"&DATE($H$5,12,1)) | D15: =IF(Settings!$B$8>0,C15/Settings!$B$8,"") | E15: =IF(D15="","",REPT("█",ROUND(MIN(D15,1)*20,0))&REPT("░",20-ROUND(MIN(D15,1)*20,0))) | F15: =SUMIFS(Projects!$J$5:$J$1000,Projects!$P$5:$P$1000,">="&DATE($H$5,11,1),Projects!$P$5:$P$1000,"<"&DATE($H$5,12,1))
A16: Dec | B16: =SUMIFS(Invoices!$E$5:$E$1000,Invoices!$C$5:$C$1000,">="&DATE($H$5,12,1),Invoices!$C$5:$C$1000,"<"&DATE($H$5+1,1,1)) | C16: =SUMIFS(Invoices!$G$5:$G$1000,Invoices!$F$5:$F$1000,">="&DATE($H$5,12,1),Invoices!$F$5:$F$1000,"<"&DATE($H$5+1,1,1)) | D16: =IF(Settings!$B$8>0,C16/Settings!$B$8,"") | E16: =IF(D16="","",REPT("█",ROUND(MIN(D16,1)*20,0))&REPT("░",20-ROUND(MIN(D16,1)*20,0))) | F16: =SUMIFS(Projects!$J$5:$J$1000,Projects!$P$5:$P$1000,">="&DATE($H$5,12,1),Projects!$P$5:$P$1000,"<"&DATE($H$5+1,1,1))
A17: Total | B17: =SUM(B5:B16) | C17: =SUM(C5:C16) | F17: =SUM(F5:F16)

Sheet Dashboard
A1: Dashboard
A2: All formulas. Locked without a password (Review → Unprotect Sheet). Column D is yours for notes.
A4: Key number | B4: Value | C4: Progress bar | D4: Your notes (editable)
A5: Monthly income goal | B5: =Settings!$B$8
A6: Collected this calendar month | B6: =SUMIFS(Invoices!$G$5:$G$1000,Invoices!$F$5:$F$1000,">="&DATE(YEAR(Settings!$B$9),MONTH(Settings!$B$9),1),Invoices!$F$5:$F$1000,"<="&Settings!$B$9)
A7: Collected in the last 30 days | B7: =SUMIFS(Invoices!$G$5:$G$1000,Invoices!$F$5:$F$1000,">="&(Settings!$B$9-29),Invoices!$F$5:$F$1000,"<="&Settings!$B$9)
A8: Progress: last 30 days vs goal | B8: =IF(B5>0,B7/B5,"") | C8: =IF(B8="","",REPT("█",ROUND(MIN(B8,1)*20,0))&REPT("░",20-ROUND(MIN(B8,1)*20,0)))
A9: Progress: this calendar month vs goal | B9: =IF(B5>0,B6/B5,"") | C9: =IF(B9="","",REPT("█",ROUND(MIN(B9,1)*20,0))&REPT("░",20-ROUND(MIN(B9,1)*20,0)))
A10: Outstanding (all unpaid balances) | B10: =SUM(Invoices!$J$5:$J$1000)
A11: Overdue amount | B11: =SUMIF(Invoices!$K$5:$K$1000,"Overdue",Invoices!$J$5:$J$1000)
A12: Overdue invoices | B12: =COUNTIF(Invoices!$K$5:$K$1000,"Overdue")
A13: Due in the next 7 days | B13: =SUMIFS(Invoices!$J$5:$J$1000,Invoices!$I$5:$I$1000,">="&Settings!$B$9,Invoices!$I$5:$I$1000,"<="&(Settings!$B$9+7))
A14: Reminders to send today | B14: =COUNTIF(Invoices!$O$5:$O$1000,">0")
A15: Average days to pay (paid in full) | B15: =IF(COUNT(Invoices!$M$5:$M$1000)=0,"–",AVERAGE(Invoices!$M$5:$M$1000))
A16: Total invoiced | B16: =SUM(Invoices!$E$5:$E$1000)
A17: Total paid | B17: =SUM(Invoices!$G$5:$G$1000)
A18: Weighted pipeline (Lead + Proposal sent) | B18: =SUM(Projects!$J$5:$J$1000)
A19: Booked work (Won + In progress) | B19: =SUMIF(Projects!$C$5:$C$1000,"Won",Projects!$D$5:$D$1000)+SUMIF(Projects!$C$5:$C$1000,"In progress",Projects!$D$5:$D$1000)
A20: Real hourly rate (Done projects) | B20: =IF(SUMIF(Projects!$C$5:$C$1000,"Done",Projects!$F$5:$F$1000)>0,SUMIF(Projects!$C$5:$C$1000,"Done",Projects!$D$5:$D$1000)/SUMIF(Projects!$C$5:$C$1000,"Done",Projects!$F$5:$F$1000),"–")
A21: Planned hourly rate (Done projects) | B21: =IF(SUMIF(Projects!$C$5:$C$1000,"Done",Projects!$E$5:$E$1000)>0,SUMIF(Projects!$C$5:$C$1000,"Done",Projects!$D$5:$D$1000)/SUMIF(Projects!$C$5:$C$1000,"Done",Projects!$E$5:$E$1000),"–")
A22: Proposals to follow up | B22: =COUNTIF(Projects!$N$5:$N$1000,"Follow up")
A24: =IF(B18<B5,"→ Weighted pipeline is below your monthly goal: send outreach and follow up on proposals this week.","")
A25: =IF(B10>B5,"→ Outstanding is above your monthly goal: ask new clients for a 50% deposit.","")
A27: NEXT MONTH | B27: =CHOOSE(MONTH(DATE(YEAR(Settings!$B$9),MONTH(Settings!$B$9)+1,1)),"Jan","Feb","Mar","Apr","May","Jun","Jul","Aug","Sep","Oct","Nov","Dec")&" "&YEAR(DATE(YEAR(Settings!$B$9),MONTH(Settings!$B$9)+1,1))
A28: Weighted pipeline expected to close next month | B28: =SUMIFS(Projects!$J$5:$J$1000,Projects!$P$5:$P$1000,">="&DATE(YEAR(Settings!$B$9),MONTH(Settings!$B$9)+1,1),Projects!$P$5:$P$1000,"<"&DATE(YEAR(Settings!$B$9),MONTH(Settings!$B$9)+2,1))
A29: Next month: weighted pipeline vs goal | B29: =IF(B5>0,B28/B5,"") | C29: =IF(B29="","",REPT("█",ROUND(MIN(B29,1)*20,0))&REPT("░",20-ROUND(MIN(B29,1)*20,0)))
A30: Gap to goal if only that pipeline closes | B30: =IF(B5>B28,B5-B28,0)
A31: Open leads/proposals with no expected close date | B31: =COUNTIF(Projects!$C$5:$C$1000,"Lead")+COUNTIF(Projects!$C$5:$C$1000,"Proposal sent")-COUNTIFS(Projects!$C$5:$C$1000,"Lead",Projects!$P$5:$P$1000,"<>")-COUNTIFS(Projects!$C$5:$C$1000,"Proposal sent",Projects!$P$5:$P$1000,"<>")
A32: =IF(B31>0,"→ Add an Expected close date (Projects column P) to every open lead and proposal.","")

Sheet Reminders Today
A1: Reminders Today
A2: Most overdue first. Click Email body, copy, paste into your email. Helper columns fill it in.
A4: # | B4: Score (helper) | C4: Invoice # | D4: Client | E4: First name | F4: Balance | G4: Days overdue | H4: Due date | I4: Send this | J4: Amount (text) | K4: Due (text) | L4: Email subject | M4: Email body
A5: 1 | B5: =IFERROR(LARGE(Invoices!$O$5:$O$1000,A5),0) | C5: =IF(B5<=0,"",INDEX(Invoices!$A$5:$A$1000,MATCH(B5,Invoices!$O$5:$O$1000,0))) | D5: =IF(B5<=0,"",INDEX(Invoices!$B$5:$B$1000,MATCH(B5,Invoices!$O$5:$O$1000,0))) | E5: =IF(C5="","",IF(IFERROR(INDEX(Clients!$B$5:$B$1000,MATCH(D5,Clients!$A$5:$A$1000,0))&"","")="","there",INDEX(Clients!$B$5:$B$1000,MATCH(D5,Clients!$A$5:$A$1000,0)))) | F5: =IF(B5<=0,"",INDEX(Invoices!$J$5:$J$1000,MATCH(B5,Invoices!$O$5:$O$1000,0))) | G5: =IF(B5<=0,"",INDEX(Invoices!$L$5:$L$1000,MATCH(B5,Invoices!$O$5:$O$1000,0))) | H5: =IF(B5<=0,"",INDEX(Invoices!$I$5:$I$1000,MATCH(B5,Invoices!$O$5:$O$1000,0))) | I5: =IF(B5<=0,"",INDEX(Invoices!$N$5:$N$1000,MATCH(B5,Invoices!$O$5:$O$1000,0))) | J5: =IF(C5="","",Settings!$B$7&IF(ROUND(F5,2)>=1000000,INT(ROUND(F5,2)/1000000)&","&RIGHT("00"&INT(MOD(ROUND(F5,2),1000000)/1000),3)&","&RIGHT(TEXT(ROUND(F5,2),"0.00"),6),IF(ROUND(F5,2)>=1000,INT(ROUND(F5,2)/1000)&","&RIGHT(TEXT(ROUND(F5,2),"0.00"),6),TEXT(ROUND(F5,2),"0.00")))) | K5: =IF(C5="","",CHOOSE(MONTH(H5),"Jan","Feb","Mar","Apr","May","Jun","Jul","Aug","Sep","Oct","Nov","Dec")&" "&DAY(H5)&", "&YEAR(H5)) | L5: =IF(C5="","",SUBSTITUTE(SUBSTITUTE(SUBSTITUTE(SUBSTITUTE(INDEX(Settings!$B$31:$B$38,MATCH(I5,Settings!$A$31:$A$38,0)),"{first}",E5),"{inv}",C5),"{due}",K5),"{days}",G5)) | M5: =IF(C5="","",SUBSTITUTE(SUBSTITUTE(SUBSTITUTE(SUBSTITUTE(SUBSTITUTE(SUBSTITUTE(SUBSTITUTE(SUBSTITUTE(INDEX(Settings!$B$31:$B$38,MATCH(I5,Settings!$A$31:$A$38,0)+1),"{first}",E5),"{inv}",C5),"{amount}",J5),"{due}",K5),"{days}",G5),"{paydate}",Settings!$C$40),"{me}",Settings!$C$41),"{latefee}",Settings!$C$42))
A6: 2 | B6: =IFERROR(LARGE(Invoices!$O$5:$O$1000,A6),0) | C6: =IF(B6<=0,"",INDEX(Invoices!$A$5:$A$1000,MATCH(B6,Invoices!$O$5:$O$1000,0))) | D6: =IF(B6<=0,"",INDEX(Invoices!$B$5:$B$1000,MATCH(B6,Invoices!$O$5:$O$1000,0))) | E6: =IF(C6="","",IF(IFERROR(INDEX(Clients!$B$5:$B$1000,MATCH(D6,Clients!$A$5:$A$1000,0))&"","")="","there",INDEX(Clients!$B$5:$B$1000,MATCH(D6,Clients!$A$5:$A$1000,0)))) | F6: =IF(B6<=0,"",INDEX(Invoices!$J$5:$J$1000,MATCH(B6,Invoices!$O$5:$O$1000,0))) | G6: =IF(B6<=0,"",INDEX(Invoices!$L$5:$L$1000,MATCH(B6,Invoices!$O$5:$O$1000,0))) | H6: =IF(B6<=0,"",INDEX(Invoices!$I$5:$I$1000,MATCH(B6,Invoices!$O$5:$O$1000,0))) | I6: =IF(B6<=0,"",INDEX(Invoices!$N$5:$N$1000,MATCH(B6,Invoices!$O$5:$O$1000,0))) | J6: =IF(C6="","",Settings!$B$7&IF(ROUND(F6,2)>=1000000,INT(ROUND(F6,2)/1000000)&","&RIGHT("00"&INT(MOD(ROUND(F6,2),1000000)/1000),3)&","&RIGHT(TEXT(ROUND(F6,2),"0.00"),6),IF(ROUND(F6,2)>=1000,INT(ROUND(F6,2)/1000)&","&RIGHT(TEXT(ROUND(F6,2),"0.00"),6),TEXT(ROUND(F6,2),"0.00")))) | K6: =IF(C6="","",CHOOSE(MONTH(H6),"Jan","Feb","Mar","Apr","May","Jun","Jul","Aug","Sep","Oct","Nov","Dec")&" "&DAY(H6)&", "&YEAR(H6)) | L6: =IF(C6="","",SUBSTITUTE(SUBSTITUTE(SUBSTITUTE(SUBSTITUTE(INDEX(Settings!$B$31:$B$38,MATCH(I6,Settings!$A$31:$A$38,0)),"{first}",E6),"{inv}",C6),"{due}",K6),"{days}",G6)) | M6: =IF(C6="","",SUBSTITUTE(SUBSTITUTE(SUBSTITUTE(SUBSTITUTE(SUBSTITUTE(SUBSTITUTE(SUBSTITUTE(SUBSTITUTE(INDEX(Settings!$B$31:$B$38,MATCH(I6,Settings!$A$31:$A$38,0)+1),"{first}",E6),"{inv}",C6),"{amount}",J6),"{due}",K6),"{days}",G6),"{paydate}",Settings!$C$40),"{me}",Settings!$C$41),"{latefee}",Settings!$C$42))
A7: 3 | B7: =IFERROR(LARGE(Invoices!$O$5:$O$1000,A7),0) | C7: =IF(B7<=0,"",INDEX(Invoices!$A$5:$A$1000,MATCH(B7,Invoices!$O$5:$O$1000,0))) | D7: =IF(B7<=0,"",INDEX(Invoices!$B$5:$B$1000,MATCH(B7,Invoices!$O$5:$O$1000,0))) | E7: =IF(C7="","",IF(IFERROR(INDEX(Clients!$B$5:$B$1000,MATCH(D7,Clients!$A$5:$A$1000,0))&"","")="","there",INDEX(Clients!$B$5:$B$1000,MATCH(D7,Clients!$A$5:$A$1000,0)))) | F7: =IF(B7<=0,"",INDEX(Invoices!$J$5:$J$1000,MATCH(B7,Invoices!$O$5:$O$1000,0))) | G7: =IF(B7<=0,"",INDEX(Invoices!$L$5:$L$1000,MATCH(B7,Invoices!$O$5:$O$1000,0))) | H7: =IF(B7<=0,"",INDEX(Invoices!$I$5:$I$1000,MATCH(B7,Invoices!$O$5:$O$1000,0))) | I7: =IF(B7<=0,"",INDEX(Invoices!$N$5:$N$1000,MATCH(B7,Invoices!$O$5:$O$1000,0))) | J7: =IF(C7="","",Settings!$B$7&IF(ROUND(F7,2)>=1000000,INT(ROUND(F7,2)/1000000)&","&RIGHT("00"&INT(MOD(ROUND(F7,2),1000000)/1000),3)&","&RIGHT(TEXT(ROUND(F7,2),"0.00"),6),IF(ROUND(F7,2)>=1000,INT(ROUND(F7,2)/1000)&","&RIGHT(TEXT(ROUND(F7,2),"0.00"),6),TEXT(ROUND(F7,2),"0.00")))) | K7: =IF(C7="","",CHOOSE(MONTH(H7),"Jan","Feb","Mar","Apr","May","Jun","Jul","Aug","Sep","Oct","Nov","Dec")&" "&DAY(H7)&", "&YEAR(H7)) | L7: =IF(C7="","",SUBSTITUTE(SUBSTITUTE(SUBSTITUTE(SUBSTITUTE(INDEX(Settings!$B$31:$B$38,MATCH(I7,Settings!$A$31:$A$38,0)),"{first}",E7),"{inv}",C7),"{due}",K7),"{days}",G7)) | M7: =IF(C7="","",SUBSTITUTE(SUBSTITUTE(SUBSTITUTE(SUBSTITUTE(SUBSTITUTE(SUBSTITUTE(SUBSTITUTE(SUBSTITUTE(INDEX(Settings!$B$31:$B$38,MATCH(I7,Settings!$A$31:$A$38,0)+1),"{first}",E7),"{inv}",C7),"{amount}",J7),"{due}",K7),"{days}",G7),"{paydate}",Settings!$C$40),"{me}",Settings!$C$41),"{latefee}",Settings!$C$42))
A8: 4 | B8: =IFERROR(LARGE(Invoices!$O$5:$O$1000,A8),0) | C8: =IF(B8<=0,"",INDEX(Invoices!$A$5:$A$1000,MATCH(B8,Invoices!$O$5:$O$1000,0))) | D8: =IF(B8<=0,"",INDEX(Invoices!$B$5:$B$1000,MATCH(B8,Invoices!$O$5:$O$1000,0))) | E8: =IF(C8="","",IF(IFERROR(INDEX(Clients!$B$5:$B$1000,MATCH(D8,Clients!$A$5:$A$1000,0))&"","")="","there",INDEX(Clients!$B$5:$B$1000,MATCH(D8,Clients!$A$5:$A$1000,0)))) | F8: =IF(B8<=0,"",INDEX(Invoices!$J$5:$J$1000,MATCH(B8,Invoices!$O$5:$O$1000,0))) | G8: =IF(B8<=0,"",INDEX(Invoices!$L$5:$L$1000,MATCH(B8,Invoices!$O$5:$O$1000,0))) | H8: =IF(B8<=0,"",INDEX(Invoices!$I$5:$I$1000,MATCH(B8,Invoices!$O$5:$O$1000,0))) | I8: =IF(B8<=0,"",INDEX(Invoices!$N$5:$N$1000,MATCH(B8,Invoices!$O$5:$O$1000,0))) | J8: =IF(C8="","",Settings!$B$7&IF(ROUND(F8,2)>=1000000,INT(ROUND(F8,2)/1000000)&","&RIGHT("00"&INT(MOD(ROUND(F8,2),1000000)/1000),3)&","&RIGHT(TEXT(ROUND(F8,2),"0.00"),6),IF(ROUND(F8,2)>=1000,INT(ROUND(F8,2)/1000)&","&RIGHT(TEXT(ROUND(F8,2),"0.00"),6),TEXT(ROUND(F8,2),"0.00")))) | K8: =IF(C8="","",CHOOSE(MONTH(H8),"Jan","Feb","Mar","Apr","May","Jun","Jul","Aug","Sep","Oct","Nov","Dec")&" "&DAY(H8)&", "&YEAR(H8)) | L8: =IF(C8="","",SUBSTITUTE(SUBSTITUTE(SUBSTITUTE(SUBSTITUTE(INDEX(Settings!$B$31:$B$38,MATCH(I8,Settings!$A$31:$A$38,0)),"{first}",E8),"{inv}",C8),"{due}",K8),"{days}",G8)) | M8: =IF(C8="","",SUBSTITUTE(SUBSTITUTE(SUBSTITUTE(SUBSTITUTE(SUBSTITUTE(SUBSTITUTE(SUBSTITUTE(SUBSTITUTE(INDEX(Settings!$B$31:$B$38,MATCH(I8,Settings!$A$31:$A$38,0)+1),"{first}",E8),"{inv}",C8),"{amount}",J8),"{due}",K8),"{days}",G8),"{paydate}",Settings!$C$40),"{me}",Settings!$C$41),"{latefee}",Settings!$C$42))
A9: 5 | B9: =IFERROR(LARGE(Invoices!$O$5:$O$1000,A9),0) | C9: =IF(B9<=0,"",INDEX(Invoices!$A$5:$A$1000,MATCH(B9,Invoices!$O$5:$O$1000,0))) | D9: =IF(B9<=0,"",INDEX(Invoices!$B$5:$B$1000,MATCH(B9,Invoices!$O$5:$O$1000,0))) | E9: =IF(C9="","",IF(IFERROR(INDEX(Clients!$B$5:$B$1000,MATCH(D9,Clients!$A$5:$A$1000,0))&"","")="","there",INDEX(Clients!$B$5:$B$1000,MATCH(D9,Clients!$A$5:$A$1000,0)))) | F9: =IF(B9<=0,"",INDEX(Invoices!$J$5:$J$1000,MATCH(B9,Invoices!$O$5:$O$1000,0))) | G9: =IF(B9<=0,"",INDEX(Invoices!$L$5:$L$1000,MATCH(B9,Invoices!$O$5:$O$1000,0))) | H9: =IF(B9<=0,"",INDEX(Invoices!$I$5:$I$1000,MATCH(B9,Invoices!$O$5:$O$1000,0))) | I9: =IF(B9<=0,"",INDEX(Invoices!$N$5:$N$1000,MATCH(B9,Invoices!$O$5:$O$1000,0))) | J9: =IF(C9="","",Settings!$B$7&IF(ROUND(F9,2)>=1000000,INT(ROUND(F9,2)/1000000)&","&RIGHT("00"&INT(MOD(ROUND(F9,2),1000000)/1000),3)&","&RIGHT(TEXT(ROUND(F9,2),"0.00"),6),IF(ROUND(F9,2)>=1000,INT(ROUND(F9,2)/1000)&","&RIGHT(TEXT(ROUND(F9,2),"0.00"),6),TEXT(ROUND(F9,2),"0.00")))) | K9: =IF(C9="","",CHOOSE(MONTH(H9),"Jan","Feb","Mar","Apr","May","Jun","Jul","Aug","Sep","Oct","Nov","Dec")&" "&DAY(H9)&", "&YEAR(H9)) | L9: =IF(C9="","",SUBSTITUTE(SUBSTITUTE(SUBSTITUTE(SUBSTITUTE(INDEX(Settings!$B$31:$B$38,MATCH(I9,Settings!$A$31:$A$38,0)),"{first}",E9),"{inv}",C9),"{due}",K9),"{days}",G9)) | M9: =IF(C9="","",SUBSTITUTE(SUBSTITUTE(SUBSTITUTE(SUBSTITUTE(SUBSTITUTE(SUBSTITUTE(SUBSTITUTE(SUBSTITUTE(INDEX(Settings!$B$31:$B$38,MATCH(I9,Settings!$A$31:$A$38,0)+1),"{first}",E9),"{inv}",C9),"{amount}",J9),"{due}",K9),"{days}",G9),"{paydate}",Settings!$C$40),"{me}",Settings!$C$41),"{latefee}",Settings!$C$42))
